Workbook

Sheet Amortización
A1: Plan de pagos del banco (crédito completo)
A2: Plan original del banco según la foto. Azul = dato de entrada · Negro = fórmula · Fondo amarillo = cuotas que no aparecen en la foto
A4: No. | B4: Fecha | C4: Cuota total | D4: Capital | E4: Interés | F4: Saldo | G4: Origen | I4: Datos del crédito
A5: 0 | B5: =J9 -> 46053 | F5: =J5 -> 100000 | G5: Desembolso | I5: Monto del crédito | J5: 100000
A6: =A5+1 -> 1 | B6: =EOMONTH(B5,1) -> 46081 | C6: =D6+E6 -> 2740.64 | D6: =MIN($J$8,F5) -> 1666.67 | E6: =ROUND(F5*$J$6*(MAX(0,DATE(YEAR(B6),1,1)-B5)/(DATE(YEAR(B5)+1,1,1)-DATE(YEAR(B5),1,1))+(B6-MAX(B5,DATE(YEAR(B6),1,1)))/(DATE(YEAR(B6)+1,1,1)-DATE(YEAR(B6),1,1))),2) -> 1073.97 | F6: =ROUND(F5-D6,2) -> 98333.33 | G6: Documento | I6: Tasa de interés anual | J6: 0.14
A7: =A6+1 -> 2 | B7: =EOMONTH(B6,1) -> 46112 | C7: =D7+E7 -> 2835.89 | D7: =MIN($J$8,F6) -> 1666.67 | E7: =ROUND(F6*$J$6*(MAX(0,DATE(YEAR(B7),1,1)-B6)/(DATE(YEAR(B6)+1,1,1)-DATE(YEAR(B6),1,1))+(B7-MAX(B6,DATE(YEAR(B7),1,1)))/(DATE(YEAR(B7)+1,1,1)-DATE(YEAR(B7),1,1))),2) -> 1169.22 | F7: =ROUND(F6-D7,2) -> 96666.66 | G7: Documento | I7: Plazo (meses) | J7: 60
A8: =A7+1 -> 3 | B8: =EOMONTH(B7,1) -> 46142 | C8: =D8+E8 -> 2779 | D8: =MIN($J$8,F7) -> 1666.67 | E8: =ROUND(F7*$J$6*(MAX(0,DATE(YEAR(B8),1,1)-B7)/(DATE(YEAR(B7)+1,1,1)-DATE(YEAR(B7),1,1))+(B8-MAX(B7,DATE(YEAR(B8),1,1)))/(DATE(YEAR(B8)+1,1,1)-DATE(YEAR(B8),1,1))),2) -> 1112.33 | F8: =ROUND(F7-D8,2) -> 94999.99 | G8: Documento | I8: Capital mensual | J8: =ROUND(J5/J7,2) -> 1666.67
A9: =A8+1 -> 4 | B9: =EOMONTH(B8,1) -> 46173 | C9: =D9+E9 -> 2796.26 | D9: =MIN($J$8,F8) -> 1666.67 | E9: =ROUND(F8*$J$6*(MAX(0,DATE(YEAR(B9),1,1)-B8)/(DATE(YEAR(B8)+1,1,1)-DATE(YEAR(B8),1,1))+(B9-MAX(B8,DATE(YEAR(B9),1,1)))/(DATE(YEAR(B9)+1,1,1)-DATE(YEAR(B9),1,1))),2) -> 1129.59 | F9: =ROUND(F8-D9,2) -> 93333.32 | G9: Documento | I9: Fecha de desembolso | J9: 46053
A10: =A9+1 -> 5 | B10: =EOMONTH(B9,1) -> 46203 | C10: =D10+E10 -> 2740.64 | D10: =MIN($J$8,F9) -> 1666.67 | E10: =ROUND(F9*$J$6*(MAX(0,DATE(YEAR(B10),1,1)-B9)/(DATE(YEAR(B9)+1,1,1)-DATE(YEAR(B9),1,1))+(B10-MAX(B9,DATE(YEAR(B10),1,1)))/(DATE(YEAR(B10)+1,1,1)-DATE(YEAR(B10),1,1))),2) -> 1073.97 | F10: =ROUND(F9-D10,2) -> 91666.65 | G10: Documento | I10: Base de cálculo | J10: Días reales / 365 (366 bisiesto)
A11: =A10+1 -> 6 | B11: =EOMONTH(B10,1) -> 46234 | C11: =D11+E11 -> 2756.62 | D11: =MIN($J$8,F10) -> 1666.67 | E11: =ROUND(F10*$J$6*(MAX(0,DATE(YEAR(B11),1,1)-B10)/(DATE(YEAR(B10)+1,1,1)-DATE(YEAR(B10),1,1))+(B11-MAX(B10,DATE(YEAR(B11),1,1)))/(DATE(YEAR(B11)+1,1,1)-DATE(YEAR(B11),1,1))),2) -> 1089.95 | F11: =ROUND(F10-D11,2) -> 89999.98 | G11: Documento
A12: =A11+1 -> 7 | B12: =EOMONTH(B11,1) -> 46265 | C12: =D12+E12 -> 2736.81 | D12: =MIN($J$8,F11) -> 1666.67 | E12: =ROUND(F11*$J$6*(MAX(0,DATE(YEAR(B12),1,1)-B11)/(DATE(YEAR(B11)+1,1,1)-DATE(YEAR(B11),1,1))+(B12-MAX(B11,DATE(YEAR(B12),1,1)))/(DATE(YEAR(B12)+1,1,1)-DATE(YEAR(B12),1,1))),2) -> 1070.14 | F12: =ROUND(F11-D12,2) -> 88333.31 | G12: Documento | I12: Resumen
A13: =A12+1 -> 8 | B13: =EOMONTH(B12,1) -> 46295 | C13: =D13+E13 -> 2683.11 | D13: =MIN($J$8,F12) -> 1666.67 | E13: =ROUND(F12*$J$6*(MAX(0,DATE(YEAR(B13),1,1)-B12)/(DATE(YEAR(B12)+1,1,1)-DATE(YEAR(B12),1,1))+(B13-MAX(B12,DATE(YEAR(B13),1,1)))/(DATE(YEAR(B13)+1,1,1)-DATE(YEAR(B13),1,1))),2) -> 1016.44 | F13: =ROUND(F12-D13,2) -> 86666.64 | G13: Documento | I13: Tasa mensual equivalente | J13: =J6/12 -> 0.011666667
A14: =A13+1 -> 9 | B14: =EOMONTH(B13,1) -> 46326 | C14: =D14+E14 -> 2697.17 | D14: =MIN($J$8,F13) -> 1666.67 | E14: =ROUND(F13*$J$6*(MAX(0,DATE(YEAR(B14),1,1)-B13)/(DATE(YEAR(B13)+1,1,1)-DATE(YEAR(B13),1,1))+(B14-MAX(B13,DATE(YEAR(B14),1,1)))/(DATE(YEAR(B14)+1,1,1)-DATE(YEAR(B14),1,1))),2) -> 1030.5 | F14: =ROUND(F13-D14,2) -> 84999.97 | G14: Documento | I14: Tasa efectiva anual (aprox.) | J14: =(1+J6/12)^12-1 -> 0.14934203
A15: =A14+1 -> 10 | B15: =EOMONTH(B14,1) -> 46356 | C15: =D15+E15 -> 2644.75 | D15: =MIN($J$8,F14) -> 1666.67 | E15: =ROUND(F14*$J$6*(MAX(0,DATE(YEAR(B15),1,1)-B14)/(DATE(YEAR(B14)+1,1,1)-DATE(YEAR(B14),1,1))+(B15-MAX(B14,DATE(YEAR(B15),1,1)))/(DATE(YEAR(B15)+1,1,1)-DATE(YEAR(B15),1,1))),2) -> 978.08 | F15: =ROUND(F14-D15,2) -> 83333.3 | G15: Documento | I15: Total de intereses | J15: =E66 -> 35533.42
A16: =A15+1 -> 11 | B16: =EOMONTH(B15,1) -> 46387 | C16: =D16+E16 -> 2657.54 | D16: =MIN($J$8,F15) -> 1666.67 | E16: =ROUND(F15*$J$6*(MAX(0,DATE(YEAR(B16),1,1)-B15)/(DATE(YEAR(B15)+1,1,1)-DATE(YEAR(B15),1,1))+(B16-MAX(B15,DATE(YEAR(B16),1,1)))/(DATE(YEAR(B16)+1,1,1)-DATE(YEAR(B16),1,1))),2) -> 990.87 | F16: =ROUND(F15-D16,2) -> 81666.63 | G16: Documento | I16: Total pagado (capital + intereses) | J16: =C66 -> 135533.42
A17: =A16+1 -> 12 | B17: =EOMONTH(B16,1) -> 46418 | C17: =D17+E17 -> 2637.72 | D17: =MIN($J$8,F16) -> 1666.67 | E17: =ROUND(F16*$J$6*(MAX(0,DATE(YEAR(B17),1,1)-B16)/(DATE(YEAR(B16)+1,1,1)-DATE(YEAR(B16),1,1))+(B17-MAX(B16,DATE(YEAR(B17),1,1)))/(DATE(YEAR(B17)+1,1,1)-DATE(YEAR(B17),1,1))),2) -> 971.05 | F17: =ROUND(F16-D17,2) -> 79999.96 | G17: Documento | I17: Intereses / monto del crédito | J17: =J15/J5 -> 0.3553342
A18: =A17+1 -> 13 | B18: =EOMONTH(B17,1) -> 46446 | C18: =D18+E18 -> 2525.85 | D18: =MIN($J$8,F17) -> 1666.67 | E18: =ROUND(F17*$J$6*(MAX(0,DATE(YEAR(B18),1,1)-B17)/(DATE(YEAR(B17)+1,1,1)-DATE(YEAR(B17),1,1))+(B18-MAX(B17,DATE(YEAR(B18),1,1)))/(DATE(YEAR(B18)+1,1,1)-DATE(YEAR(B18),1,1))),2) -> 859.18 | F18: =ROUND(F17-D18,2) -> 78333.29 | G18: Documento | I18: Fecha del último pago | J18: =B65 -> 47879
A19: =A18+1 -> 14 | B19: =EOMONTH(B18,1) -> 46477 | C19: =D19+E19 -> 2598.09 | D19: =MIN($J$8,F18) -> 1666.67 | E19: =ROUND(F18*$J$6*(MAX(0,DATE(YEAR(B19),1,1)-B18)/(DATE(YEAR(B18)+1,1,1)-DATE(YEAR(B18),1,1))+(B19-MAX(B18,DATE(YEAR(B19),1,1)))/(DATE(YEAR(B19)+1,1,1)-DATE(YEAR(B19),1,1))),2) -> 931.42 | F19: =ROUND(F18-D19,2) -> 76666.62 | G19: Documento | I19: Saldo final | J19: =F65 -> 0
A20: =A19+1 -> 15 | B20: =EOMONTH(B19,1) -> 46507 | C20: =D20+E20 -> 2548.86 | D20: =MIN($J$8,F19) -> 1666.67 | E20: =ROUND(F19*$J$6*(MAX(0,DATE(YEAR(B20),1,1)-B19)/(DATE(YEAR(B19)+1,1,1)-DATE(YEAR(B19),1,1))+(B20-MAX(B19,DATE(YEAR(B20),1,1)))/(DATE(YEAR(B20)+1,1,1)-DATE(YEAR(B20),1,1))),2) -> 882.19 | F20: =ROUND(F19-D20,2) -> 74999.95 | G20: Documento | I20: Diferencia de intereses vs. foto | J20: =SUMPRODUCT(ABS(E6:E52-'Foto original'!E5:E51)) -> 0
A21: =A20+1 -> 16 | B21: =EOMONTH(B20,1) -> 46538 | C21: =D21+E21 -> 2558.45 | D21: =MIN($J$8,F20) -> 1666.67 | E21: =ROUND(F20*$J$6*(MAX(0,DATE(YEAR(B21),1,1)-B20)/(DATE(YEAR(B20)+1,1,1)-DATE(YEAR(B20),1,1))+(B21-MAX(B20,DATE(YEAR(B21),1,1)))/(DATE(YEAR(B21)+1,1,1)-DATE(YEAR(B21),1,1))),2) -> 891.78 | F21: =ROUND(F20-D21,2) -> 73333.28 | G21: Documento | I21: Diferencia de saldos vs. foto | J21: =SUMPRODUCT(ABS(F6:F52-'Foto original'!F5:F51)) -> 0
A22: =A21+1 -> 17 | B22: =EOMONTH(B21,1) -> 46568 | C22: =D22+E22 -> 2510.51 | D22: =MIN($J$8,F21) -> 1666.67 | E22: =ROUND(F21*$J$6*(MAX(0,DATE(YEAR(B22),1,1)-B21)/(DATE(YEAR(B21)+1,1,1)-DATE(YEAR(B21),1,1))+(B22-MAX(B21,DATE(YEAR(B22),1,1)))/(DATE(YEAR(B22)+1,1,1)-DATE(YEAR(B22),1,1))),2) -> 843.84 | F22: =ROUND(F21-D22,2) -> 71666.61 | G22: Documento
A23: =A22+1 -> 18 | B23: =EOMONTH(B22,1) -> 46599 | C23: =D23+E23 -> 2518.82 | D23: =MIN($J$8,F22) -> 1666.67 | E23: =ROUND(F22*$J$6*(MAX(0,DATE(YEAR(B23),1,1)-B22)/(DATE(YEAR(B22)+1,1,1)-DATE(YEAR(B22),1,1))+(B23-MAX(B22,DATE(YEAR(B23),1,1)))/(DATE(YEAR(B23)+1,1,1)-DATE(YEAR(B23),1,1))),2) -> 852.15 | F23: =ROUND(F22-D23,2) -> 69999.94 | G23: Documento | I23: División entre Gaby y Gerson
A24: =A23+1 -> 19 | B24: =EOMONTH(B23,1) -> 46630 | C24: =D24+E24 -> 2499 | D24: =MIN($J$8,F23) -> 1666.67 | E24: =ROUND(F23*$J$6*(MAX(0,DATE(YEAR(B24),1,1)-B23)/(DATE(YEAR(B23)+1,1,1)-DATE(YEAR(B23),1,1))+(B24-MAX(B23,DATE(YEAR(B24),1,1)))/(DATE(YEAR(B24)+1,1,1)-DATE(YEAR(B24),1,1))),2) -> 832.33 | F24: =ROUND(F23-D24,2) -> 68333.27 | G24: Documento | I24: Gastos administrativos descontados | J24: 2000
A25: =A24+1 -> 20 | B25: =EOMONTH(B24,1) -> 46660 | C25: =D25+E25 -> 2452.97 | D25: =MIN($J$8,F24) -> 1666.67 | E25: =ROUND(F24*$J$6*(MAX(0,DATE(YEAR(B25),1,1)-B24)/(DATE(YEAR(B24)+1,1,1)-DATE(YEAR(B24),1,1))+(B25-MAX(B24,DATE(YEAR(B25),1,1)))/(DATE(YEAR(B25)+1,1,1)-DATE(YEAR(B25),1,1))),2) -> 786.3 | F25: =ROUND(F24-D25,2) -> 66666.6 | G25: Documento | I25: Monto recibido por Gaby | J25: 48000
A26: =A25+1 -> 21 | B26: =EOMONTH(B25,1) -> 46691 | C26: =D26+E26 -> 2459.36 | D26: =MIN($J$8,F25) -> 1666.67 | E26: =ROUND(F25*$J$6*(MAX(0,DATE(YEAR(B26),1,1)-B25)/(DATE(YEAR(B25)+1,1,1)-DATE(YEAR(B25),1,1))+(B26-MAX(B25,DATE(YEAR(B26),1,1)))/(DATE(YEAR(B26)+1,1,1)-DATE(YEAR(B26),1,1))),2) -> 792.69 | F26: =ROUND(F25-D26,2) -> 64999.93 | G26: Documento | I26: Monto recibido por Gerson | J26: 50000
A27: =A26+1 -> 22 | B27: =EOMONTH(B26,1) -> 46721 | C27: =D27+E27 -> 2414.61 | D27: =MIN($J$8,F26) -> 1666.67 | E27: =ROUND(F26*$J$6*(MAX(0,DATE(YEAR(B27),1,1)-B26)/(DATE(YEAR(B26)+1,1,1)-DATE(YEAR(B26),1,1))+(B27-MAX(B26,DATE(YEAR(B27),1,1)))/(DATE(YEAR(B27)+1,1,1)-DATE(YEAR(B27),1,1))),2) -> 747.94 | F27: =ROUND(F26-D27,2) -> 63333.26 | G27: Documento | I27: Verificación: monto − recibido − gastos | J27: =J5-J24-J25-J26 -> 0
A28: =A27+1 -> 23 | B28: =EOMONTH(B27,1) -> 46752 | C28: =D28+E28 -> 2419.73 | D28: =MIN($J$8,F27) -> 1666.67 | E28: =ROUND(F27*$J$6*(MAX(0,DATE(YEAR(B28),1,1)-B27)/(DATE(YEAR(B27)+1,1,1)-DATE(YEAR(B27),1,1))+(B28-MAX(B27,DATE(YEAR(B28),1,1)))/(DATE(YEAR(B28)+1,1,1)-DATE(YEAR(B28),1,1))),2) -> 753.06 | F28: =ROUND(F27-D28,2) -> 61666.59 | G28: Documento | I28: % de los gastos que asume Gaby | J28: 0.5
A29: =A28+1 -> 24 | B29: =EOMONTH(B28,1) -> 46783 | C29: =D29+E29 -> 2397.97 | D29: =MIN($J$8,F28) -> 1666.67 | E29: =ROUND(F28*$J$6*(MAX(0,DATE(YEAR(B29),1,1)-B28)/(DATE(YEAR(B28)+1,1,1)-DATE(YEAR(B28),1,1))+(B29-MAX(B28,DATE(YEAR(B29),1,1)))/(DATE(YEAR(B29)+1,1,1)-DATE(YEAR(B29),1,1))),2) -> 731.3 | F29: =ROUND(F28-D29,2) -> 59999.92 | G29: Documento | I29: Deuda inicial de Gaby | J29: =J25+J24*J28 -> 49000
A30: =A29+1 -> 25 | B30: =EOMONTH(B29,1) -> 46812 | C30: =D30+E30 -> 2332.24 | D30: =MIN($J$8,F29) -> 1666.67 | E30: =ROUND(F29*$J$6*(MAX(0,DATE(YEAR(B30),1,1)-B29)/(DATE(YEAR(B29)+1,1,1)-DATE(YEAR(B29),1,1))+(B30-MAX(B29,DATE(YEAR(B30),1,1)))/(DATE(YEAR(B30)+1,1,1)-DATE(YEAR(B30),1,1))),2) -> 665.57 | F30: =ROUND(F29-D30,2) -> 58333.25 | G30: Documento | I30: Deuda inicial de Gerson | J30: =J26+J24*(1-J28) -> 51000
A31: =A30+1 -> 26 | B31: =EOMONTH(B30,1) -> 46843 | C31: =D31+E31 -> 2358.38 | D31: =MIN($J$8,F30) -> 1666.67 | E31: =ROUND(F30*$J$6*(MAX(0,DATE(YEAR(B31),1,1)-B30)/(DATE(YEAR(B30)+1,1,1)-DATE(YEAR(B30),1,1))+(B31-MAX(B30,DATE(YEAR(B31),1,1)))/(DATE(YEAR(B31)+1,1,1)-DATE(YEAR(B31),1,1))),2) -> 691.71 | F31: =ROUND(F30-D31,2) -> 56666.58 | G31: Documento | I31: Participación inicial de Gaby | J31: =J29/J5 -> 0.49
A32: =A31+1 -> 27 | B32: =EOMONTH(B31,1) -> 46873 | C32: =D32+E32 -> 2316.94 | D32: =MIN($J$8,F31) -> 1666.67 | E32: =ROUND(F31*$J$6*(MAX(0,DATE(YEAR(B32),1,1)-B31)/(DATE(YEAR(B31)+1,1,1)-DATE(YEAR(B31),1,1))+(B32-MAX(B31,DATE(YEAR(B32),1,1)))/(DATE(YEAR(B32)+1,1,1)-DATE(YEAR(B32),1,1))),2) -> 650.27 | F32: =ROUND(F31-D32,2) -> 54999.91 | G32: Documento | I32: Participación inicial de Gerson | J32: =J30/J5 -> 0.51
A33: =A32+1 -> 28 | B33: =EOMONTH(B32,1) -> 46904 | C33: =D33+E33 -> 2318.85 | D33: =MIN($J$8,F32) -> 1666.67 | E33: =ROUND(F32*$J$6*(MAX(0,DATE(YEAR(B33),1,1)-B32)/(DATE(YEAR(B32)+1,1,1)-DATE(YEAR(B32),1,1))+(B33-MAX(B32,DATE(YEAR(B33),1,1)))/(DATE(YEAR(B33)+1,1,1)-DATE(YEAR(B33),1,1))),2) -> 652.18 | F33: =ROUND(F32-D33,2) -> 53333.24 | G33: Documento
A34: =A33+1 -> 29 | B34: =EOMONTH(B33,1) -> 46934 | C34: =D34+E34 -> 2278.69 | D34: =MIN($J$8,F33) -> 1666.67 | E34: =ROUND(F33*$J$6*(MAX(0,DATE(YEAR(B34),1,1)-B33)/(DATE(YEAR(B33)+1,1,1)-DATE(YEAR(B33),1,1))+(B34-MAX(B33,DATE(YEAR(B34),1,1)))/(DATE(YEAR(B34)+1,1,1)-DATE(YEAR(B34),1,1))),2) -> 612.02 | F34: =ROUND(F33-D34,2) -> 51666.57 | G34: Documento
A35: =A34+1 -> 30 | B35: =EOMONTH(B34,1) -> 46965 | C35: =D35+E35 -> 2279.33 | D35: =MIN($J$8,F34) -> 1666.67 | E35: =ROUND(F34*$J$6*(MAX(0,DATE(YEAR(B35),1,1)-B34)/(DATE(YEAR(B34)+1,1,1)-DATE(YEAR(B34),1,1))+(B35-MAX(B34,DATE(YEAR(B35),1,1)))/(DATE(YEAR(B35)+1,1,1)-DATE(YEAR(B35),1,1))),2) -> 612.66 | F35: =ROUND(F34-D35,2) -> 49999.9 | G35: Documento
A36: =A35+1 -> 31 | B36: =EOMONTH(B35,1) -> 46996 | C36: =D36+E36 -> 2259.56 | D36: =MIN($J$8,F35) -> 1666.67 | E36: =ROUND(F35*$J$6*(MAX(0,DATE(YEAR(B36),1,1)-B35)/(DATE(YEAR(B35)+1,1,1)-DATE(YEAR(B35),1,1))+(B36-MAX(B35,DATE(YEAR(B36),1,1)))/(DATE(YEAR(B36)+1,1,1)-DATE(YEAR(B36),1,1))),2) -> 592.89 | F36: =ROUND(F35-D36,2) -> 48333.23 | G36: Documento
A37: =A36+1 -> 32 | B37: =EOMONTH(B36,1) -> 47026 | C37: =D37+E37 -> 2221.31 | D37: =MIN($J$8,F36) -> 1666.67 | E37: =ROUND(F36*$J$6*(MAX(0,DATE(YEAR(B37),1,1)-B36)/(DATE(YEAR(B36)+1,1,1)-DATE(YEAR(B36),1,1))+(B37-MAX(B36,DATE(YEAR(B37),1,1)))/(DATE(YEAR(B37)+1,1,1)-DATE(YEAR(B37),1,1))),2) -> 554.64 | F37: =ROUND(F36-D37,2) -> 46666.56 | G37: Documento
A38: =A37+1 -> 33 | B38: =EOMONTH(B37,1) -> 47057 | C38: =D38+E38 -> 2220.04 | D38: =MIN($J$8,F37) -> 1666.67 | E38: =ROUND(F37*$J$6*(MAX(0,DATE(YEAR(B38),1,1)-B37)/(DATE(YEAR(B37)+1,1,1)-DATE(YEAR(B37),1,1))+(B38-MAX(B37,DATE(YEAR(B38),1,1)))/(DATE(YEAR(B38)+1,1,1)-DATE(YEAR(B38),1,1))),2) -> 553.37 | F38: =ROUND(F37-D38,2) -> 44999.89 | G38: Documento
A39: =A38+1 -> 34 | B39: =EOMONTH(B38,1) -> 47087 | C39: =D39+E39 -> 2183.06 | D39: =MIN($J$8,F38) -> 1666.67 | E39: =ROUND(F38*$J$6*(MAX(0,DATE(YEAR(B39),1,1)-B38)/(DATE(YEAR(B38)+1,1,1)-DATE(YEAR(B38),1,1))+(B39-MAX(B38,DATE(YEAR(B39),1,1)))/(DATE(YEAR(B39)+1,1,1)-DATE(YEAR(B39),1,1))),2) -> 516.39 | F39: =ROUND(F38-D39,2) -> 43333.22 | G39: Documento
A40: =A39+1 -> 35 | B40: =EOMONTH(B39,1) -> 47118 | C40: =D40+E40 -> 2180.51 | D40: =MIN($J$8,F39) -> 1666.67 | E40: =ROUND(F39*$J$6*(MAX(0,DATE(YEAR(B40),1,1)-B39)/(DATE(YEAR(B39)+1,1,1)-DATE(YEAR(B39),1,1))+(B40-MAX(B39,DATE(YEAR(B40),1,1)))/(DATE(YEAR(B40)+1,1,1)-DATE(YEAR(B40),1,1))),2) -> 513.84 | F40: =ROUND(F39-D40,2) -> 41666.55 | G40: Documento
A41: =A40+1 -> 36 | B41: =EOMONTH(B40,1) -> 47149 | C41: =D41+E41 -> 2162.06 | D41: =MIN($J$8,F40) -> 1666.67 | E41: =ROUND(F40*$J$6*(MAX(0,DATE(YEAR(B41),1,1)-B40)/(DATE(YEAR(B40)+1,1,1)-DATE(YEAR(B40),1,1))+(B41-MAX(B40,DATE(YEAR(B41),1,1)))/(DATE(YEAR(B41)+1,1,1)-DATE(YEAR(B41),1,1))),2) -> 495.39 | F41: =ROUND(F40-D41,2) -> 39999.88 | G41: Documento
...

Sheet Gaby
A1: Crédito individual – Gaby
A2: Columna amarilla «Pagado» = lo que pagó de verdad (en blanco si aún no paga; entonces se usa la cuota programada) · Negro = fórmula · Verde = tomado de otra hoja
A4: No. | B4: Fecha | C4: Saldo inicial | D4: Interés | E4: Cuota programada | F4: Pagado | G4: Pago aplicado | H4: Capital abonado | I4: Saldo final | K4: Resumen – Gaby
A5: =Amortización!A5 -> 0 | B5: =Amortización!B5 -> 46053 | I5: =Amortización!$J$29 -> 49000 | K5: Monto recibido | L5: =Amortización!$J$25 -> 48000
A6: =Amortización!A6 -> 1 | B6: =Amortización!B6 -> 46081 | C6: =I5 -> 49000 | D6: =ROUND(C6*Amortización!$J$6*(MAX(0,DATE(YEAR(B6),1,1)-B5)/(DATE(YEAR(B5)+1,1,1)-DATE(YEAR(B5),1,1))+(B6-MAX(B5,DATE(YEAR(B6),1,1)))/(DATE(YEAR(B6)+1,1,1)-DATE(YEAR(B6),1,1))),2) -> 526.25 | E6: =IF(C6<=0,0,MIN(C6,ROUND(Amortización!D6*C6/Amortización!F5,2))+D6) -> 1342.92 | F6: 2677.85 | G6: =IF(F6="",E6,F6) -> 2677.85 | H6: =G6-D6 -> 2151.6 | I6: =ROUND(C6-H6,2) -> 46848.4 | K6: Gastos administrativos que le tocan | L6: =Amortización!$J$24*Amortización!$J$28 -> 1000
A7: =Amortización!A7 -> 2 | B7: =Amortización!B7 -> 46112 | C7: =I6 -> 46848.4 | D7: =ROUND(C7*Amortización!$J$6*(MAX(0,DATE(YEAR(B7),1,1)-B6)/(DATE(YEAR(B6)+1,1,1)-DATE(YEAR(B6),1,1))+(B7-MAX(B6,DATE(YEAR(B7),1,1)))/(DATE(YEAR(B7)+1,1,1)-DATE(YEAR(B7),1,1))),2) -> 557.05 | E7: =IF(C7<=0,0,MIN(C7,ROUND(Amortización!D7*C7/Amortización!F6,2))+D7) -> 1351.09 | F7: 2653.08 | G7: =IF(F7="",E7,F7) -> 2653.08 | H7: =G7-D7 -> 2096.03 | I7: =ROUND(C7-H7,2) -> 44752.37 | K7: Deuda inicial (capital) | L7: =I5 -> 49000
A8: =Amortización!A8 -> 3 | B8: =Amortización!B8 -> 46142 | C8: =I7 -> 44752.37 | D8: =ROUND(C8*Amortización!$J$6*(MAX(0,DATE(YEAR(B8),1,1)-B7)/(DATE(YEAR(B7)+1,1,1)-DATE(YEAR(B7),1,1))+(B8-MAX(B7,DATE(YEAR(B8),1,1)))/(DATE(YEAR(B8)+1,1,1)-DATE(YEAR(B8),1,1))),2) -> 514.96 | E8: =IF(C8<=0,0,MIN(C8,ROUND(Amortización!D8*C8/Amortización!F7,2))+D8) -> 1286.55 | F8: 2628.31 | G8: =IF(F8="",E8,F8) -> 2628.31 | H8: =G8-D8 -> 2113.35 | I8: =ROUND(C8-H8,2) -> 42639.02
A9: =Amortización!A9 -> 4 | B9: =Amortización!B9 -> 46173 | C9: =I8 -> 42639.02 | D9: =ROUND(C9*Amortización!$J$6*(MAX(0,DATE(YEAR(B9),1,1)-B8)/(DATE(YEAR(B8)+1,1,1)-DATE(YEAR(B8),1,1))+(B9-MAX(B8,DATE(YEAR(B9),1,1)))/(DATE(YEAR(B9)+1,1,1)-DATE(YEAR(B9),1,1))),2) -> 507 | E9: =IF(C9<=0,0,MIN(C9,ROUND(Amortización!D9*C9/Amortización!F8,2))+D9) -> 1255.05 | F9: 2603.54 | G9: =IF(F9="",E9,F9) -> 2603.54 | H9: =G9-D9 -> 2096.54 | I9: =ROUND(C9-H9,2) -> 40542.48 | K9: A la fecha
A10: =Amortización!A10 -> 5 | B10: =Amortización!B10 -> 46203 | C10: =I9 -> 40542.48 | D10: =ROUND(C10*Amortización!$J$6*(MAX(0,DATE(YEAR(B10),1,1)-B9)/(DATE(YEAR(B9)+1,1,1)-DATE(YEAR(B9),1,1))+(B10-MAX(B9,DATE(YEAR(B10),1,1)))/(DATE(YEAR(B10)+1,1,1)-DATE(YEAR(B10),1,1))),2) -> 466.52 | E10: =IF(C10<=0,0,MIN(C10,ROUND(Amortización!D10*C10/Amortización!F9,2))+D10) -> 1190.49 | F10: 2578.76 | G10: =IF(F10="",E10,F10) -> 2578.76 | H10: =G10-D10 -> 2112.24 | I10: =ROUND(C10-H10,2) -> 38430.24 | K10: Cuotas con pago registrado | L10: =COUNT(F6:F65) -> 8
A11: =Amortización!A11 -> 6 | B11: =Amortización!B11 -> 46234 | C11: =I10 -> 38430.24 | D11: =ROUND(C11*Amortización!$J$6*(MAX(0,DATE(YEAR(B11),1,1)-B10)/(DATE(YEAR(B10)+1,1,1)-DATE(YEAR(B10),1,1))+(B11-MAX(B10,DATE(YEAR(B11),1,1)))/(DATE(YEAR(B11)+1,1,1)-DATE(YEAR(B11),1,1))),2) -> 456.95 | E11: =IF(C11<=0,0,MIN(C11,ROUND(Amortización!D11*C11/Amortización!F10,2))+D11) -> 1155.68 | F11: 2553.99 | G11: =IF(F11="",E11,F11) -> 2553.99 | H11: =G11-D11 -> 2097.04 | I11: =ROUND(C11-H11,2) -> 36333.2 | K11: Total pagado | L11: =SUM(F6:F65) -> 20729.2
A12: =Amortización!A12 -> 7 | B12: =Amortización!B12 -> 46265 | C12: =I11 -> 36333.2 | D12: =ROUND(C12*Amortización!$J$6*(MAX(0,DATE(YEAR(B12),1,1)-B11)/(DATE(YEAR(B11)+1,1,1)-DATE(YEAR(B11),1,1))+(B12-MAX(B11,DATE(YEAR(B12),1,1)))/(DATE(YEAR(B12)+1,1,1)-DATE(YEAR(B12),1,1))),2) -> 432.02 | E12: =IF(C12<=0,0,MIN(C12,ROUND(Amortización!D12*C12/Amortización!F11,2))+D12) -> 1104.86 | F12: 2529.22 | G12: =IF(F12="",E12,F12) -> 2529.22 | H12: =G12-D12 -> 2097.2 | I12: =ROUND(C12-H12,2) -> 34236 | K12: Intereses pagados | L12: =SUMPRODUCT((F6:F65<>"")*D6:D65) -> 3854.7
A13: =Amortización!A13 -> 8 | B13: =Amortización!B13 -> 46295 | C13: =I12 -> 34236 | D13: =ROUND(C13*Amortización!$J$6*(MAX(0,DATE(YEAR(B13),1,1)-B12)/(DATE(YEAR(B12)+1,1,1)-DATE(YEAR(B12),1,1))+(B13-MAX(B12,DATE(YEAR(B13),1,1)))/(DATE(YEAR(B13)+1,1,1)-DATE(YEAR(B13),1,1))),2) -> 393.95 | E13: =IF(C13<=0,0,MIN(C13,ROUND(Amortización!D13*C13/Amortización!F12,2))+D13) -> 1039.91 | F13: 2504.45 | G13: =IF(F13="",E13,F13) -> 2504.45 | H13: =G13-D13 -> 2110.5 | I13: =ROUND(C13-H13,2) -> 32125.5 | K13: Capital abonado | L13: =SUMPRODUCT((F6:F65<>"")*H6:H65) -> 16874.5
A14: =Amortización!A14 -> 9 | B14: =Amortización!B14 -> 46326 | C14: =I13 -> 32125.5 | D14: =ROUND(C14*Amortización!$J$6*(MAX(0,DATE(YEAR(B14),1,1)-B13)/(DATE(YEAR(B13)+1,1,1)-DATE(YEAR(B13),1,1))+(B14-MAX(B13,DATE(YEAR(B14),1,1)))/(DATE(YEAR(B14)+1,1,1)-DATE(YEAR(B14),1,1))),2) -> 381.99 | E14: =IF(C14<=0,0,MIN(C14,ROUND(Amortización!D14*C14/Amortización!F13,2))+D14) -> 999.79 | G14: =IF(F14="",E14,F14) -> 999.79 | H14: =G14-D14 -> 617.8 | I14: =ROUND(C14-H14,2) -> 31507.7 | K14: Saldo de capital hoy | L14: =INDEX(I5:I65,L10+1) -> 32125.5
A15: =Amortización!A15 -> 10 | B15: =Amortización!B15 -> 46356 | C15: =I14 -> 31507.7 | D15: =ROUND(C15*Amortización!$J$6*(MAX(0,DATE(YEAR(B15),1,1)-B14)/(DATE(YEAR(B14)+1,1,1)-DATE(YEAR(B14),1,1))+(B15-MAX(B14,DATE(YEAR(B15),1,1)))/(DATE(YEAR(B15)+1,1,1)-DATE(YEAR(B15),1,1))),2) -> 362.55 | E15: =IF(C15<=0,0,MIN(C15,ROUND(Amortización!D15*C15/Amortización!F14,2))+D15) -> 980.35 | G15: =IF(F15="",E15,F15) -> 980.35 | H15: =G15-D15 -> 617.8 | I15: =ROUND(C15-H15,2) -> 30889.9
A16: =Amortización!A16 -> 11 | B16: =Amortización!B16 -> 46387 | C16: =I15 -> 30889.9 | D16: =ROUND(C16*Amortización!$J$6*(MAX(0,DATE(YEAR(B16),1,1)-B15)/(DATE(YEAR(B15)+1,1,1)-DATE(YEAR(B15),1,1))+(B16-MAX(B15,DATE(YEAR(B16),1,1)))/(DATE(YEAR(B16)+1,1,1)-DATE(YEAR(B16),1,1))),2) -> 367.29 | E16: =IF(C16<=0,0,MIN(C16,ROUND(Amortización!D16*C16/Amortización!F15,2))+D16) -> 985.09 | G16: =IF(F16="",E16,F16) -> 985.09 | H16: =G16-D16 -> 617.8 | I16: =ROUND(C16-H16,2) -> 30272.1 | K16: Próxima cuota
A17: =Amortización!A17 -> 12 | B17: =Amortización!B17 -> 46418 | C17: =I16 -> 30272.1 | D17: =ROUND(C17*Amortización!$J$6*(MAX(0,DATE(YEAR(B17),1,1)-B16)/(DATE(YEAR(B16)+1,1,1)-DATE(YEAR(B16),1,1))+(B17-MAX(B16,DATE(YEAR(B17),1,1)))/(DATE(YEAR(B17)+1,1,1)-DATE(YEAR(B17),1,1))),2) -> 359.95 | E17: =IF(C17<=0,0,MIN(C17,ROUND(Amortización!D17*C17/Amortización!F16,2))+D17) -> 977.75 | G17: =IF(F17="",E17,F17) -> 977.75 | H17: =G17-D17 -> 617.8 | I17: =ROUND(C17-H17,2) -> 29654.3 | K17: Fecha | L17: =IF(L10>=60,"",INDEX(B6:B65,L10+1)) -> 46326
A18: =Amortización!A18 -> 13 | B18: =Amortización!B18 -> 46446 | C18: =I17 -> 29654.3 | D18: =ROUND(C18*Amortización!$J$6*(MAX(0,DATE(YEAR(B18),1,1)-B17)/(DATE(YEAR(B17)+1,1,1)-DATE(YEAR(B17),1,1))+(B18-MAX(B17,DATE(YEAR(B18),1,1)))/(DATE(YEAR(B18)+1,1,1)-DATE(YEAR(B18),1,1))),2) -> 318.48 | E18: =IF(C18<=0,0,MIN(C18,ROUND(Amortización!D18*C18/Amortización!F17,2))+D18) -> 936.28 | G18: =IF(F18="",E18,F18) -> 936.28 | H18: =G18-D18 -> 617.8 | I18: =ROUND(C18-H18,2) -> 29036.5 | K18: Cuota programada | L18: =IF(L10>=60,"",INDEX(E6:E65,L10+1)) -> 999.79
A19: =Amortización!A19 -> 14 | B19: =Amortización!B19 -> 46477 | C19: =I18 -> 29036.5 | D19: =ROUND(C19*Amortización!$J$6*(MAX(0,DATE(YEAR(B19),1,1)-B18)/(DATE(YEAR(B18)+1,1,1)-DATE(YEAR(B18),1,1))+(B19-MAX(B18,DATE(YEAR(B19),1,1)))/(DATE(YEAR(B19)+1,1,1)-DATE(YEAR(B19),1,1))),2) -> 345.26 | E19: =IF(C19<=0,0,MIN(C19,ROUND(Amortización!D19*C19/Amortización!F18,2))+D19) -> 963.06 | G19: =IF(F19="",E19,F19) -> 963.06 | H19: =G19-D19 -> 617.8 | I19: =ROUND(C19-H19,2) -> 28418.7 | K19: Pago para liquidar todo su saldo | L19: =IF(L10>=60,"",INDEX(C6:C65,L10+1)+INDEX(D6:D65,L10+1)) -> 32507.49
A20: =Amortización!A20 -> 15 | B20: =Amortización!B20 -> 46507 | C20: =I19 -> 28418.7 | D20: =ROUND(C20*Amortización!$J$6*(MAX(0,DATE(YEAR(B20),1,1)-B19)/(DATE(YEAR(B19)+1,1,1)-DATE(YEAR(B19),1,1))+(B20-MAX(B19,DATE(YEAR(B20),1,1)))/(DATE(YEAR(B20)+1,1,1)-DATE(YEAR(B20),1,1))),2) -> 327.01 | E20: =IF(C20<=0,0,MIN(C20,ROUND(Amortización!D20*C20/Amortización!F19,2))+D20) -> 944.81 | G20: =IF(F20="",E20,F20) -> 944.81 | H20: =G20-D20 -> 617.8 | I20: =ROUND(C20-H20,2) -> 27800.9
A21: =Amortización!A21 -> 16 | B21: =Amortización!B21 -> 46538 | C21: =I20 -> 27800.9 | D21: =ROUND(C21*Amortización!$J$6*(MAX(0,DATE(YEAR(B21),1,1)-B20)/(DATE(YEAR(B20)+1,1,1)-DATE(YEAR(B20),1,1))+(B21-MAX(B20,DATE(YEAR(B21),1,1)))/(DATE(YEAR(B21)+1,1,1)-DATE(YEAR(B21),1,1))),2) -> 330.56 | E21: =IF(C21<=0,0,MIN(C21,ROUND(Amortización!D21*C21/Amortización!F20,2))+D21) -> 948.36 | G21: =IF(F21="",E21,F21) -> 948.36 | H21: =G21-D21 -> 617.8 | I21: =ROUND(C21-H21,2) -> 27183.1 | K21: Proyección hasta el final
A22: =Amortización!A22 -> 17 | B22: =Amortización!B22 -> 46568 | C22: =I21 -> 27183.1 | D22: =ROUND(C22*Amortización!$J$6*(MAX(0,DATE(YEAR(B22),1,1)-B21)/(DATE(YEAR(B21)+1,1,1)-DATE(YEAR(B21),1,1))+(B22-MAX(B21,DATE(YEAR(B22),1,1)))/(DATE(YEAR(B22)+1,1,1)-DATE(YEAR(B22),1,1))),2) -> 312.79 | E22: =IF(C22<=0,0,MIN(C22,ROUND(Amortización!D22*C22/Amortización!F21,2))+D22) -> 930.59 | G22: =IF(F22="",E22,F22) -> 930.59 | H22: =G22-D22 -> 617.8 | I22: =ROUND(C22-H22,2) -> 26565.3 | K22: Total de intereses | L22: =D66 -> 13788.04
A23: =Amortización!A23 -> 18 | B23: =Amortización!B23 -> 46599 | C23: =I22 -> 26565.3 | D23: =ROUND(C23*Amortización!$J$6*(MAX(0,DATE(YEAR(B23),1,1)-B22)/(DATE(YEAR(B22)+1,1,1)-DATE(YEAR(B22),1,1))+(B23-MAX(B22,DATE(YEAR(B23),1,1)))/(DATE(YEAR(B23)+1,1,1)-DATE(YEAR(B23),1,1))),2) -> 315.87 | E23: =IF(C23<=0,0,MIN(C23,ROUND(Amortización!D23*C23/Amortización!F22,2))+D23) -> 933.67 | G23: =IF(F23="",E23,F23) -> 933.67 | H23: =G23-D23 -> 617.8 | I23: =ROUND(C23-H23,2) -> 25947.5 | K23: Total a pagar (pagado + programado) | L23: =G66 -> 62788.04
A24: =Amortización!A24 -> 19 | B24: =Amortización!B24 -> 46630 | C24: =I23 -> 25947.5 | D24: =ROUND(C24*Amortización!$J$6*(MAX(0,DATE(YEAR(B24),1,1)-B23)/(DATE(YEAR(B23)+1,1,1)-DATE(YEAR(B23),1,1))+(B24-MAX(B23,DATE(YEAR(B24),1,1)))/(DATE(YEAR(B24)+1,1,1)-DATE(YEAR(B24),1,1))),2) -> 308.53 | E24: =IF(C24<=0,0,MIN(C24,ROUND(Amortización!D24*C24/Amortización!F23,2))+D24) -> 926.33 | G24: =IF(F24="",E24,F24) -> 926.33 | H24: =G24-D24 -> 617.8 | I24: =ROUND(C24-H24,2) -> 25329.7 | K24: Último pago | L24: =INDEX(B6:B65,MAX(1,COUNTIF(C6:C65,">0.005"))) -> 47879
A25: =Amortización!A25 -> 20 | B25: =Amortización!B25 -> 46660 | C25: =I24 -> 25329.7 | D25: =ROUND(C25*Amortización!$J$6*(MAX(0,DATE(YEAR(B25),1,1)-B24)/(DATE(YEAR(B24)+1,1,1)-DATE(YEAR(B24),1,1))+(B25-MAX(B24,DATE(YEAR(B25),1,1)))/(DATE(YEAR(B25)+1,1,1)-DATE(YEAR(B25),1,1))),2) -> 291.47 | E25: =IF(C25<=0,0,MIN(C25,ROUND(Amortización!D25*C25/Amortización!F24,2))+D25) -> 909.27 | G25: =IF(F25="",E25,F25) -> 909.27 | H25: =G25-D25 -> 617.8 | I25: =ROUND(C25-H25,2) -> 24711.9
A26: =Amortización!A26 -> 21 | B26: =Amortización!B26 -> 46691 | C26: =I25 -> 24711.9 | D26: =ROUND(C26*Amortización!$J$6*(MAX(0,DATE(YEAR(B26),1,1)-B25)/(DATE(YEAR(B25)+1,1,1)-DATE(YEAR(B25),1,1))+(B26-MAX(B25,DATE(YEAR(B26),1,1)))/(DATE(YEAR(B26)+1,1,1)-DATE(YEAR(B26),1,1))),2) -> 293.83 | E26: =IF(C26<=0,0,MIN(C26,ROUND(Amortización!D26*C26/Amortización!F25,2))+D26) -> 911.63 | G26: =IF(F26="",E26,F26) -> 911.63 | H26: =G26-D26 -> 617.8 | I26: =ROUND(C26-H26,2) -> 24094.1
A27: =Amortización!A27 -> 22 | B27: =Amortización!B27 -> 46721 | C27: =I26 -> 24094.1 | D27: =ROUND(C27*Amortización!$J$6*(MAX(0,DATE(YEAR(B27),1,1)-B26)/(DATE(YEAR(B26)+1,1,1)-DATE(YEAR(B26),1,1))+(B27-MAX(B26,DATE(YEAR(B27),1,1)))/(DATE(YEAR(B27)+1,1,1)-DATE(YEAR(B27),1,1))),2) -> 277.25 | E27: =IF(C27<=0,0,MIN(C27,ROUND(Amortización!D27*C27/Amortización!F26,2))+D27) -> 895.05 | G27: =IF(F27="",E27,F27) -> 895.05 | H27: =G27-D27 -> 617.8 | I27: =ROUND(C27-H27,2) -> 23476.3
A28: =Amortización!A28 -> 23 | B28: =Amortización!B28 -> 46752 | C28: =I27 -> 23476.3 | D28: =ROUND(C28*Amortización!$J$6*(MAX(0,DATE(YEAR(B28),1,1)-B27)/(DATE(YEAR(B27)+1,1,1)-DATE(YEAR(B27),1,1))+(B28-MAX(B27,DATE(YEAR(B28),1,1)))/(DATE(YEAR(B28)+1,1,1)-DATE(YEAR(B28),1,1))),2) -> 279.14 | E28: =IF(C28<=0,0,MIN(C28,ROUND(Amortización!D28*C28/Amortización!F27,2))+D28) -> 896.94 | G28: =IF(F28="",E28,F28) -> 896.94 | H28: =G28-D28 -> 617.8 | I28: =ROUND(C28-H28,2) -> 22858.5
A29: =Amortización!A29 -> 24 | B29: =Amortización!B29 -> 46783 | C29: =I28 -> 22858.5 | D29: =ROUND(C29*Amortización!$J$6*(MAX(0,DATE(YEAR(B29),1,1)-B28)/(DATE(YEAR(B28)+1,1,1)-DATE(YEAR(B28),1,1))+(B29-MAX(B28,DATE(YEAR(B29),1,1)))/(DATE(YEAR(B29)+1,1,1)-DATE(YEAR(B29),1,1))),2) -> 271.08 | E29: =IF(C29<=0,0,MIN(C29,ROUND(Amortización!D29*C29/Amortización!F28,2))+D29) -> 888.88 | G29: =IF(F29="",E29,F29) -> 888.88 | H29: =G29-D29 -> 617.8 | I29: =ROUND(C29-H29,2) -> 22240.7
A30: =Amortización!A30 -> 25 | B30: =Amortización!B30 -> 46812 | C30: =I29 -> 22240.7 | D30: =ROUND(C30*Amortización!$J$6*(MAX(0,DATE(YEAR(B30),1,1)-B29)/(DATE(YEAR(B29)+1,1,1)-DATE(YEAR(B29),1,1))+(B30-MAX(B29,DATE(YEAR(B30),1,1)))/(DATE(YEAR(B30)+1,1,1)-DATE(YEAR(B30),1,1))),2) -> 246.71 | E30: =IF(C30<=0,0,MIN(C30,ROUND(Amortización!D30*C30/Amortización!F29,2))+D30) -> 864.51 | G30: =IF(F30="",E30,F30) -> 864.51 | H30: =G30-D30 -> 617.8 | I30: =ROUND(C30-H30,2) -> 21622.9
A31: =Amortización!A31 -> 26 | B31: =Amortización!B31 -> 46843 | C31: =I30 -> 21622.9 | D31: =ROUND(C31*Amortización!$J$6*(MAX(0,DATE(YEAR(B31),1,1)-B30)/(DATE(YEAR(B30)+1,1,1)-DATE(YEAR(B30),1,1))+(B31-MAX(B30,DATE(YEAR(B31),1,1)))/(DATE(YEAR(B31)+1,1,1)-DATE(YEAR(B31),1,1))),2) -> 256.4 | E31: =IF(C31<=0,0,MIN(C31,ROUND(Amortización!D31*C31/Amortización!F30,2))+D31) -> 874.2 | G31: =IF(F31="",E31,F31) -> 874.2 | H31: =G31-D31 -> 617.8 | I31: =ROUND(C31-H31,2) -> 21005.1
A32: =Amortización!A32 -> 27 | B32: =Amortización!B32 -> 46873 | C32: =I31 -> 21005.1 | D32: =ROUND(C32*Amortización!$J$6*(MAX(0,DATE(YEAR(B32),1,1)-B31)/(DATE(YEAR(B31)+1,1,1)-DATE(YEAR(B31),1,1))+(B32-MAX(B31,DATE(YEAR(B32),1,1)))/(DATE(YEAR(B32)+1,1,1)-DATE(YEAR(B32),1,1))),2) -> 241.04 | E32: =IF(C32<=0,0,MIN(C32,ROUND(Amortización!D32*C32/Amortización!F31,2))+D32) -> 858.84 | G32: =IF(F32="",E32,F32) -> 858.84 | H32: =G32-D32 -> 617.8 | I32: =ROUND(C32-H32,2) -> 20387.3
A33: =Amortización!A33 -> 28 | B33: =Amortización!B33 -> 46904 | C33: =I32 -> 20387.3 | D33: =ROUND(C33*Amortización!$J$6*(MAX(0,DATE(YEAR(B33),1,1)-B32)/(DATE(YEAR(B32)+1,1,1)-DATE(YEAR(B32),1,1))+(B33-MAX(B32,DATE(YEAR(B33),1,1)))/(DATE(YEAR(B33)+1,1,1)-DATE(YEAR(B33),1,1))),2) -> 241.75 | E33: =IF(C33<=0,0,MIN(C33,ROUND(Amortización!D33*C33/Amortización!F32,2))+D33) -> 859.55 | G33: =IF(F33="",E33,F33) -> 859.55 | H33: =G33-D33 -> 617.8 | I33: =ROUND(C33-H33,2) -> 19769.5
A34: =Amortización!A34 -> 29 | B34: =Amortización!B34 -> 46934 | C34: =I33 -> 19769.5 | D34: =ROUND(C34*Amortización!$J$6*(MAX(0,DATE(YEAR(B34),1,1)-B33)/(DATE(YEAR(B33)+1,1,1)-DATE(YEAR(B33),1,1))+(B34-MAX(B33,DATE(YEAR(B34),1,1)))/(DATE(YEAR(B34)+1,1,1)-DATE(YEAR(B34),1,1))),2) -> 226.86 | E34: =IF(C34<=0,0,MIN(C34,ROUND(Amortización!D34*C34/Amortización!F33,2))+D34) -> 844.66 | G34: =IF(F34="",E34,F34) -> 844.66 | H34: =G34-D34 -> 617.8 | I34: =ROUND(C34-H34,2) -> 19151.7
A35: =Amortización!A35 -> 30 | B35: =Amortización!B35 -> 46965 | C35: =I34 -> 19151.7 | D35: =ROUND(C35*Amortización!$J$6*(MAX(0,DATE(YEAR(B35),1,1)-B34)/(DATE(YEAR(B34)+1,1,1)-DATE(YEAR(B34),1,1))+(B35-MAX(B34,DATE(YEAR(B35),1,1)))/(DATE(YEAR(B35)+1,1,1)-DATE(YEAR(B35),1,1))),2) -> 227.1 | E35: =IF(C35<=0,0,MIN(C35,ROUND(Amortización!D35*C35/Amortización!F34,2))+D35) -> 844.9 | G35: =IF(F35="",E35,F35) -> 844.9 | H35: =G35-D35 -> 617.8 | I35: =ROUND(C35-H35,2) -> 18533.9
A36: =Amortización!A36 -> 31 | B36: =Amortización!B36 -> 46996 | C36: =I35 -> 18533.9 | D36: =ROUND(C36*Amortización!$J$6*(MAX(0,DATE(YEAR(B36),1,1)-B35)/(DATE(YEAR(B35)+1,1,1)-DATE(YEAR(B35),1,1))+(B36-MAX(B35,DATE(YEAR(B36),1,1)))/(DATE(YEAR(B36)+1,1,1)-DATE(YEAR(B36),1,1))),2) -> 219.77 | E36: =IF(C36<=0,0,MIN(C36,ROUND(Amortización!D36*C36/Amortización!F35,2))+D36) -> 837.57 | G36: =IF(F36="",E36,F36) -> 837.57 | H36: =G36-D36 -> 617.8 | I36: =ROUND(C36-H36,2) -> 17916.1
... A65: =Amortización!A65 -> 60 | B65: =Amortización!B65 -> 47879 | C65: =I64 -> 617.72 | D65: =ROUND(C65*Amortización!$J$6*(MAX(0,DATE(YEAR(B65),1,1)-B64)/(DATE(YEAR(B64)+1,1,1)-DATE(YEAR(B64),1,1))+(B65-MAX(B64,DATE(YEAR(B65),1,1)))/(DATE(YEAR(B65)+1,1,1)-DATE(YEAR(B65),1,1))),2) -> 7.34 | E65: =IF(C65<=0,0,MIN(C65,ROUND(Amortización!D65*C65/Amortización!F64,2))+D65) -> 625.06 | G65: =IF(F65="",E65,F65) -> 625.06 | H65: =G65-D65 -> 617.72 | I65: =ROUND(C65-H65,2) -> 0
B66: Total | D66: =SUM(D6:D65) -> 13788.04 | F66: =SUM(F6:F65) -> 20729.2 | G66: =SUM(G6:G65) -> 62788.04 | H66: =SUM(H6:H65) -> 49000

Sheet Gerson
A1: Crédito individual – Gerson
A2: Columna amarilla «Pagado» = lo que pagó de verdad (en blanco si aún no paga; entonces se usa la cuota programada) · Negro = fórmula · Verde = tomado de otra hoja
A4: No. | B4: Fecha | C4: Saldo inicial | D4: Interés | E4: Cuota programada | F4: Pagado | G4: Pago aplicado | H4: Capital abonado | I4: Saldo final | K4: Resumen – Gerson
A5: =Amortización!A5 -> 0 | B5: =Amortización!B5 -> 46053 | I5: =Amortización!$J$30 -> 51000 | K5: Monto recibido | L5: =Amortización!$J$26 -> 50000
A6: =Amortización!A6 -> 1 | B6: =Amortización!B6 -> 46081 | C6: =I5 -> 51000 | D6: =ROUND((Gaby!C6+C6)*Amortización!$J$6*(MAX(0,DATE(YEAR(B6),1,1)-B5)/(DATE(YEAR(B5)+1,1,1)-DATE(YEAR(B5),1,1))+(B6-MAX(B5,DATE(YEAR(B6),1,1)))/(DATE(YEAR(B6)+1,1,1)-DATE(YEAR(B6),1,1))),2)-Gaby!D6 -> 547.72 | E6: =IF(C6<=0,0,MIN(C6,ROUND(Amortización!D6*(Gaby!C6+C6)/Amortización!F5,2)-(Gaby!E6-Gaby!D6))+D6) -> 1397.72 | F6: =IF(Gaby!F6="","",ROUND(Amortización!C6-Gaby!F6,2)) -> 62.79 | G6: =IF(F6="",E6,F6) -> 62.79 | H6: =G6-D6 -> -484.93 | I6: =ROUND(C6-H6,2) -> 51484.93 | K6: Gastos administrativos que le tocan | L6: =Amortización!$J$24*(1-Amortización!$J$28) -> 1000
A7: =Amortización!A7 -> 2 | B7: =Amortización!B7 -> 46112 | C7: =I6 -> 51484.93 | D7: =ROUND((Gaby!C7+C7)*Amortización!$J$6*(MAX(0,DATE(YEAR(B7),1,1)-B6)/(DATE(YEAR(B6)+1,1,1)-DATE(YEAR(B6),1,1))+(B7-MAX(B6,DATE(YEAR(B7),1,1)))/(DATE(YEAR(B7)+1,1,1)-DATE(YEAR(B7),1,1))),2)-Gaby!D7 -> 612.17 | E7: =IF(C7<=0,0,MIN(C7,ROUND(Amortización!D7*(Gaby!C7+C7)/Amortización!F6,2)-(Gaby!E7-Gaby!D7))+D7) -> 1484.8 | F7: =IF(Gaby!F7="","",ROUND(Amortización!C7-Gaby!F7,2)) -> 182.81 | G7: =IF(F7="",E7,F7) -> 182.81 | H7: =G7-D7 -> -429.36 | I7: =ROUND(C7-H7,2) -> 51914.29 | K7: Deuda inicial (capital) | L7: =I5 -> 51000
A8: =Amortización!A8 -> 3 | B8: =Amortización!B8 -> 46142 | C8: =I7 -> 51914.29 | D8: =ROUND((Gaby!C8+C8)*Amortización!$J$6*(MAX(0,DATE(YEAR(B8),1,1)-B7)/(DATE(YEAR(B7)+1,1,1)-DATE(YEAR(B7),1,1))+(B8-MAX(B7,DATE(YEAR(B8),1,1)))/(DATE(YEAR(B8)+1,1,1)-DATE(YEAR(B8),1,1))),2)-Gaby!D8 -> 597.37 | E8: =IF(C8<=0,0,MIN(C8,ROUND(Amortización!D8*(Gaby!C8+C8)/Amortización!F7,2)-(Gaby!E8-Gaby!D8))+D8) -> 1492.45 | F8: =IF(Gaby!F8="","",ROUND(Amortización!C8-Gaby!F8,2)) -> 150.69 | G8: =IF(F8="",E8,F8) -> 150.69 | H8: =G8-D8 -> -446.68 | I8: =ROUND(C8-H8,2) -> 52360.97
A9: =Amortización!A9 -> 4 | B9: =Amortización!B9 -> 46173 | C9: =I8 -> 52360.97 | D9: =ROUND((Gaby!C9+C9)*Amortización!$J$6*(MAX(0,DATE(YEAR(B9),1,1)-B8)/(DATE(YEAR(B8)+1,1,1)-DATE(YEAR(B8),1,1))+(B9-MAX(B8,DATE(YEAR(B9),1,1)))/(DATE(YEAR(B9)+1,1,1)-DATE(YEAR(B9),1,1))),2)-Gaby!D9 -> 622.59 | E9: =IF(C9<=0,0,MIN(C9,ROUND(Amortización!D9*(Gaby!C9+C9)/Amortización!F8,2)-(Gaby!E9-Gaby!D9))+D9) -> 1541.21 | F9: =IF(Gaby!F9="","",ROUND(Amortización!C9-Gaby!F9,2)) -> 192.72 | G9: =IF(F9="",E9,F9) -> 192.72 | H9: =G9-D9 -> -429.87 | I9: =ROUND(C9-H9,2) -> 52790.84 | K9: A la fecha
A10: =Amortización!A10 -> 5 | B10: =Amortización!B10 -> 46203 | C10: =I9 -> 52790.84 | D10: =ROUND((Gaby!C10+C10)*Amortización!$J$6*(MAX(0,DATE(YEAR(B10),1,1)-B9)/(DATE(YEAR(B9)+1,1,1)-DATE(YEAR(B9),1,1))+(B10-MAX(B9,DATE(YEAR(B10),1,1)))/(DATE(YEAR(B10)+1,1,1)-DATE(YEAR(B10),1,1))),2)-Gaby!D10 -> 607.45 | E10: =IF(C10<=0,0,MIN(C10,ROUND(Amortización!D10*(Gaby!C10+C10)/Amortización!F9,2)-(Gaby!E10-Gaby!D10))+D10) -> 1550.15 | F10: =IF(Gaby!F10="","",ROUND(Amortización!C10-Gaby!F10,2)) -> 161.88 | G10: =IF(F10="",E10,F10) -> 161.88 | H10: =G10-D10 -> -445.57 | I10: =ROUND(C10-H10,2) -> 53236.41 | K10: Cuotas con pago registrado | L10: =COUNT(F6:F65) -> 8
A11: =Amortización!A11 -> 6 | B11: =Amortización!B11 -> 46234 | C11: =I10 -> 53236.41 | D11: =ROUND((Gaby!C11+C11)*Amortización!$J$6*(MAX(0,DATE(YEAR(B11),1,1)-B10)/(DATE(YEAR(B10)+1,1,1)-DATE(YEAR(B10),1,1))+(B11-MAX(B10,DATE(YEAR(B11),1,1)))/(DATE(YEAR(B11)+1,1,1)-DATE(YEAR(B11),1,1))),2)-Gaby!D11 -> 633 | E11: =IF(C11<=0,0,MIN(C11,ROUND(Amortización!D11*(Gaby!C11+C11)/Amortización!F10,2)-(Gaby!E11-Gaby!D11))+D11) -> 1600.94 | F11: =IF(Gaby!F11="","",ROUND(Amortización!C11-Gaby!F11,2)) -> 202.63 | G11: =IF(F11="",E11,F11) -> 202.63 | H11: =G11-D11 -> -430.37 | I11: =ROUND(C11-H11,2) -> 53666.78 | K11: Total pagado | L11: =SUM(F6:F65) -> 1339.77
A12: =Amortización!A12 -> 7 | B12: =Amortización!B12 -> 46265 | C12: =I11 -> 53666.78 | D12: =ROUND((Gaby!C12+C12)*Amortización!$J$6*(MAX(0,DATE(YEAR(B12),1,1)-B11)/(DATE(YEAR(B11)+1,1,1)-DATE(YEAR(B11),1,1))+(B12-MAX(B11,DATE(YEAR(B12),1,1)))/(DATE(YEAR(B12)+1,1,1)-DATE(YEAR(B12),1,1))),2)-Gaby!D12 -> 638.12 | E12: =IF(C12<=0,0,MIN(C12,ROUND(Amortización!D12*(Gaby!C12+C12)/Amortización!F11,2)-(Gaby!E12-Gaby!D12))+D12) -> 1631.95 | F12: =IF(Gaby!F12="","",ROUND(Amortización!C12-Gaby!F12,2)) -> 207.59 | G12: =IF(F12="",E12,F12) -> 207.59 | H12: =G12-D12 -> -430.53 | I12: =ROUND(C12-H12,2) -> 54097.31 | K12: Intereses pagados | L12: =SUMPRODUCT((F6:F65<>"")*D6:D65) -> 4880.91
A13: =Amortización!A13 -> 8 | B13: =Amortización!B13 -> 46295 | C13: =I12 -> 54097.31 | D13: =ROUND((Gaby!C13+C13)*Amortización!$J$6*(MAX(0,DATE(YEAR(B13),1,1)-B12)/(DATE(YEAR(B12)+1,1,1)-DATE(YEAR(B12),1,1))+(B13-MAX(B12,DATE(YEAR(B13),1,1)))/(DATE(YEAR(B13)+1,1,1)-DATE(YEAR(B13),1,1))),2)-Gaby!D13 -> 622.49 | E13: =IF(C13<=0,0,MIN(C13,ROUND(Amortización!D13*(Gaby!C13+C13)/Amortización!F12,2)-(Gaby!E13-Gaby!D13))+D13) -> 1643.2 | F13: =IF(Gaby!F13="","",ROUND(Amortización!C13-Gaby!F13,2)) -> 178.66 | G13: =IF(F13="",E13,F13) -> 178.66 | H13: =G13-D13 -> -443.83 | I13: =ROUND(C13-H13,2) -> 54541.14 | K13: Capital abonado | L13: =SUMPRODUCT((F6:F65<>"")*H6:H65) -> -3541.14
A14: =Amortización!A14 -> 9 | B14: =Amortización!B14 -> 46326 | C14: =I13 -> 54541.14 | D14: =ROUND((Gaby!C14+C14)*Amortización!$J$6*(MAX(0,DATE(YEAR(B14),1,1)-B13)/(DATE(YEAR(B13)+1,1,1)-DATE(YEAR(B13),1,1))+(B14-MAX(B13,DATE(YEAR(B14),1,1)))/(DATE(YEAR(B14)+1,1,1)-DATE(YEAR(B14),1,1))),2)-Gaby!D14 -> 648.51 | E14: =IF(C14<=0,0,MIN(C14,ROUND(Amortización!D14*(Gaby!C14+C14)/Amortización!F13,2)-(Gaby!E14-Gaby!D14))+D14) -> 1697.38 | G14: =IF(F14="",E14,F14) -> 1697.38 | H14: =G14-D14 -> 1048.87 | I14: =ROUND(C14-H14,2) -> 53492.27 | K14: Saldo de capital hoy | L14: =INDEX(I5:I65,L10+1) -> 54541.14
A15: =Amortización!A15 -> 10 | B15: =Amortización!B15 -> 46356 | C15: =I14 -> 53492.27 | D15: =ROUND((Gaby!C15+C15)*Amortización!$J$6*(MAX(0,DATE(YEAR(B15),1,1)-B14)/(DATE(YEAR(B14)+1,1,1)-DATE(YEAR(B14),1,1))+(B15-MAX(B14,DATE(YEAR(B15),1,1)))/(DATE(YEAR(B15)+1,1,1)-DATE(YEAR(B15),1,1))),2)-Gaby!D15 -> 615.53 | E15: =IF(C15<=0,0,MIN(C15,ROUND(Amortización!D15*(Gaby!C15+C15)/Amortización!F14,2)-(Gaby!E15-Gaby!D15))+D15) -> 1664.4 | G15: =IF(F15="",E15,F15) -> 1664.4 | H15: =G15-D15 -> 1048.87 | I15: =ROUND(C15-H15,2) -> 52443.4
A16: =Amortización!A16 -> 11 | B16: =Amortización!B16 -> 46387 | C16: =I15 -> 52443.4 | D16: =ROUND((Gaby!C16+C16)*Amortización!$J$6*(MAX(0,DATE(YEAR(B16),1,1)-B15)/(DATE(YEAR(B15)+1,1,1)-DATE(YEAR(B15),1,1))+(B16-MAX(B15,DATE(YEAR(B16),1,1)))/(DATE(YEAR(B16)+1,1,1)-DATE(YEAR(B16),1,1))),2)-Gaby!D16 -> 623.58 | E16: =IF(C16<=0,0,MIN(C16,ROUND(Amortización!D16*(Gaby!C16+C16)/Amortización!F15,2)-(Gaby!E16-Gaby!D16))+D16) -> 1672.45 | G16: =IF(F16="",E16,F16) -> 1672.45 | H16: =G16-D16 -> 1048.87 | I16: =ROUND(C16-H16,2) -> 51394.53 | K16: Próxima cuota
A17: =Amortización!A17 -> 12 | B17: =Amortización!B17 -> 46418 | C17: =I16 -> 51394.53 | D17: =ROUND((Gaby!C17+C17)*Amortización!$J$6*(MAX(0,DATE(YEAR(B17),1,1)-B16)/(DATE(YEAR(B16)+1,1,1)-DATE(YEAR(B16),1,1))+(B17-MAX(B16,DATE(YEAR(B17),1,1)))/(DATE(YEAR(B17)+1,1,1)-DATE(YEAR(B17),1,1))),2)-Gaby!D17 -> 611.1 | E17: =IF(C17<=0,0,MIN(C17,ROUND(Amortización!D17*(Gaby!C17+C17)/Amortización!F16,2)-(Gaby!E17-Gaby!D17))+D17) -> 1659.97 | G17: =IF(F17="",E17,F17) -> 1659.97 | H17: =G17-D17 -> 1048.87 | I17: =ROUND(C17-H17,2) -> 50345.66 | K17: Fecha | L17: =IF(L10>=60,"",INDEX(B6:B65,L10+1)) -> 46326
A18: =Amortización!A18 -> 13 | B18: =Amortización!B18 -> 46446 | C18: =I17 -> 50345.66 | D18: =ROUND((Gaby!C18+C18)*Amortización!$J$6*(MAX(0,DATE(YEAR(B18),1,1)-B17)/(DATE(YEAR(B17)+1,1,1)-DATE(YEAR(B17),1,1))+(B18-MAX(B17,DATE(YEAR(B18),1,1)))/(DATE(YEAR(B18)+1,1,1)-DATE(YEAR(B18),1,1))),2)-Gaby!D18 -> 540.7 | E18: =IF(C18<=0,0,MIN(C18,ROUND(Amortización!D18*(Gaby!C18+C18)/Amortización!F17,2)-(Gaby!E18-Gaby!D18))+D18) -> 1589.57 | G18: =IF(F18="",E18,F18) -> 1589.57 | H18: =G18-D18 -> 1048.87 | I18: =ROUND(C18-H18,2) -> 49296.79 | K18: Cuota programada | L18: =IF(L10>=60,"",INDEX(E6:E65,L10+1)) -> 1697.38
A19: =Amortización!A19 -> 14 | B19: =Amortización!B19 -> 46477 | C19: =I18 -> 49296.79 | D19: =ROUND((Gaby!C19+C19)*Amortización!$J$6*(MAX(0,DATE(YEAR(B19),1,1)-B18)/(DATE(YEAR(B18)+1,1,1)-DATE(YEAR(B18),1,1))+(B19-MAX(B18,DATE(YEAR(B19),1,1)))/(DATE(YEAR(B19)+1,1,1)-DATE(YEAR(B19),1,1))),2)-Gaby!D19 -> 586.16 | E19: =IF(C19<=0,0,MIN(C19,ROUND(Amortización!D19*(Gaby!C19+C19)/Amortización!F18,2)-(Gaby!E19-Gaby!D19))+D19) -> 1635.03 | G19: =IF(F19="",E19,F19) -> 1635.03 | H19: =G19-D19 -> 1048.87 | I19: =ROUND(C19-H19,2) -> 48247.92 | K19: Pago para liquidar todo su saldo | L19: =IF(L10>=60,"",INDEX(C6:C65,L10+1)+INDEX(D6:D65,L10+1)) -> 55189.65
A20: =Amortización!A20 -> 15 | B20: =Amortización!B20 -> 46507 | C20: =I19 -> 48247.92 | D20: =ROUND((Gaby!C20+C20)*Amortización!$J$6*(MAX(0,DATE(YEAR(B20),1,1)-B19)/(DATE(YEAR(B19)+1,1,1)-DATE(YEAR(B19),1,1))+(B20-MAX(B19,DATE(YEAR(B20),1,1)))/(DATE(YEAR(B20)+1,1,1)-DATE(YEAR(B20),1,1))),2)-Gaby!D20 -> 555.18 | E20: =IF(C20<=0,0,MIN(C20,ROUND(Amortización!D20*(Gaby!C20+C20)/Amortización!F19,2)-(Gaby!E20-Gaby!D20))+D20) -> 1604.05 | G20: =IF(F20="",E20,F20) -> 1604.05 | H20: =G20-D20 -> 1048.87 | I20: =ROUND(C20-H20,2) -> 47199.05
A21: =Amortización!A21 -> 16 | B21: =Amortización!B21 -> 46538 | C21: =I20 -> 47199.05 | D21: =ROUND((Gaby!C21+C21)*Amortización!$J$6*(MAX(0,DATE(YEAR(B21),1,1)-B20)/(DATE(YEAR(B20)+1,1,1)-DATE(YEAR(B20),1,1))+(B21-MAX(B20,DATE(YEAR(B21),1,1)))/(DATE(YEAR(B21)+1,1,1)-DATE(YEAR(B21),1,1))),2)-Gaby!D21 -> 561.22 | E21: =IF(C21<=0,0,MIN(C21,ROUND(Amortización!D21*(Gaby!C21+C21)/Amortización!F20,2)-(Gaby!E21-Gaby!D21))+D21) -> 1610.09 | G21: =IF(F21="",E21,F21) -> 1610.09 | H21: =G21-D21 -> 1048.87 | I21: =ROUND(C21-H21,2) -> 46150.18 | K21: Proyección hasta el final
A22: =Amortización!A22 -> 17 | B22: =Amortización!B22 -> 46568 | C22: =I21 -> 46150.18 | D22: =ROUND((Gaby!C22+C22)*Amortización!$J$6*(MAX(0,DATE(YEAR(B22),1,1)-B21)/(DATE(YEAR(B21)+1,1,1)-DATE(YEAR(B21),1,1))+(B22-MAX(B21,DATE(YEAR(B22),1,1)))/(DATE(YEAR(B22)+1,1,1)-DATE(YEAR(B22),1,1))),2)-Gaby!D22 -> 531.05 | E22: =IF(C22<=0,0,MIN(C22,ROUND(Amortización!D22*(Gaby!C22+C22)/Amortización!F21,2)-(Gaby!E22-Gaby!D22))+D22) -> 1579.92 | G22: =IF(F22="",E22,F22) -> 1579.92 | H22: =G22-D22 -> 1048.87 | I22: =ROUND(C22-H22,2) -> 45101.31 | K22: Total de intereses | L22: =D66 -> 21745.38
A23: =Amortización!A23 -> 18 | B23: =Amortización!B23 -> 46599 | C23: =I22 -> 45101.31 | D23: =ROUND((Gaby!C23+C23)*Amortización!$J$6*(MAX(0,DATE(YEAR(B23),1,1)-B22)/(DATE(YEAR(B22)+1,1,1)-DATE(YEAR(B22),1,1))+(B23-MAX(B22,DATE(YEAR(B23),1,1)))/(DATE(YEAR(B23)+1,1,1)-DATE(YEAR(B23),1,1))),2)-Gaby!D23 -> 536.28 | E23: =IF(C23<=0,0,MIN(C23,ROUND(Amortización!D23*(Gaby!C23+C23)/Amortización!F22,2)-(Gaby!E23-Gaby!D23))+D23) -> 1585.15 | G23: =IF(F23="",E23,F23) -> 1585.15 | H23: =G23-D23 -> 1048.87 | I23: =ROUND(C23-H23,2) -> 44052.44 | K23: Total a pagar (pagado + programado) | L23: =G66 -> 72745.38
A24: =Amortización!A24 -> 19 | B24: =Amortización!B24 -> 46630 | C24: =I23 -> 44052.44 | D24: =ROUND((Gaby!C24+C24)*Amortización!$J$6*(MAX(0,DATE(YEAR(B24),1,1)-B23)/(DATE(YEAR(B23)+1,1,1)-DATE(YEAR(B23),1,1))+(B24-MAX(B23,DATE(YEAR(B24),1,1)))/(DATE(YEAR(B24)+1,1,1)-DATE(YEAR(B24),1,1))),2)-Gaby!D24 -> 523.8 | E24: =IF(C24<=0,0,MIN(C24,ROUND(Amortización!D24*(Gaby!C24+C24)/Amortización!F23,2)-(Gaby!E24-Gaby!D24))+D24) -> 1572.67 | G24: =IF(F24="",E24,F24) -> 1572.67 | H24: =G24-D24 -> 1048.87 | I24: =ROUND(C24-H24,2) -> 43003.57 | K24: Último pago | L24: =INDEX(B6:B65,MAX(1,COUNTIF(C6:C65,">0.005"))) -> 47879
A25: =Amortización!A25 -> 20 | B25: =Amortización!B25 -> 46660 | C25: =I24 -> 43003.57 | D25: =ROUND((Gaby!C25+C25)*Amortización!$J$6*(MAX(0,DATE(YEAR(B25),1,1)-B24)/(DATE(YEAR(B24)+1,1,1)-DATE(YEAR(B24),1,1))+(B25-MAX(B24,DATE(YEAR(B25),1,1)))/(DATE(YEAR(B25)+1,1,1)-DATE(YEAR(B25),1,1))),2)-Gaby!D25 -> 494.83 | E25: =IF(C25<=0,0,MIN(C25,ROUND(Amortización!D25*(Gaby!C25+C25)/Amortización!F24,2)-(Gaby!E25-Gaby!D25))+D25) -> 1543.7 | G25: =IF(F25="",E25,F25) -> 1543.7 | H25: =G25-D25 -> 1048.87 | I25: =ROUND(C25-H25,2) -> 41954.7
A26: =Amortización!A26 -> 21 | B26: =Amortización!B26 -> 46691 | C26: =I25 -> 41954.7 | D26: =ROUND((Gaby!C26+C26)*Amortización!$J$6*(MAX(0,DATE(YEAR(B26),1,1)-B25)/(DATE(YEAR(B25)+1,1,1)-DATE(YEAR(B25),1,1))+(B26-MAX(B25,DATE(YEAR(B26),1,1)))/(DATE(YEAR(B26)+1,1,1)-DATE(YEAR(B26),1,1))),2)-Gaby!D26 -> 498.86 | E26: =IF(C26<=0,0,MIN(C26,ROUND(Amortización!D26*(Gaby!C26+C26)/Amortización!F25,2)-(Gaby!E26-Gaby!D26))+D26) -> 1547.73 | G26: =IF(F26="",E26,F26) -> 1547.73 | H26: =G26-D26 -> 1048.87 | I26: =ROUND(C26-H26,2) -> 40905.83
A27: =Amortización!A27 -> 22 | B27: =Amortización!B27 -> 46721 | C27: =I26 -> 40905.83 | D27: =ROUND((Gaby!C27+C27)*Amortización!$J$6*(MAX(0,DATE(YEAR(B27),1,1)-B26)/(DATE(YEAR(B26)+1,1,1)-DATE(YEAR(B26),1,1))+(B27-MAX(B26,DATE(YEAR(B27),1,1)))/(DATE(YEAR(B27)+1,1,1)-DATE(YEAR(B27),1,1))),2)-Gaby!D27 -> 470.69 | E27: =IF(C27<=0,0,MIN(C27,ROUND(Amortización!D27*(Gaby!C27+C27)/Amortización!F26,2)-(Gaby!E27-Gaby!D27))+D27) -> 1519.56 | G27: =IF(F27="",E27,F27) -> 1519.56 | H27: =G27-D27 -> 1048.87 | I27: =ROUND(C27-H27,2) -> 39856.96
A28: =Amortización!A28 -> 23 | B28: =Amortización!B28 -> 46752 | C28: =I27 -> 39856.96 | D28: =ROUND((Gaby!C28+C28)*Amortización!$J$6*(MAX(0,DATE(YEAR(B28),1,1)-B27)/(DATE(YEAR(B27)+1,1,1)-DATE(YEAR(B27),1,1))+(B28-MAX(B27,DATE(YEAR(B28),1,1)))/(DATE(YEAR(B28)+1,1,1)-DATE(YEAR(B28),1,1))),2)-Gaby!D28 -> 473.92 | E28: =IF(C28<=0,0,MIN(C28,ROUND(Amortización!D28*(Gaby!C28+C28)/Amortización!F27,2)-(Gaby!E28-Gaby!D28))+D28) -> 1522.79 | G28: =IF(F28="",E28,F28) -> 1522.79 | H28: =G28-D28 -> 1048.87 | I28: =ROUND(C28-H28,2) -> 38808.09
A29: =Amortización!A29 -> 24 | B29: =Amortización!B29 -> 46783 | C29: =I28 -> 38808.09 | D29: =ROUND((Gaby!C29+C29)*Amortización!$J$6*(MAX(0,DATE(YEAR(B29),1,1)-B28)/(DATE(YEAR(B28)+1,1,1)-DATE(YEAR(B28),1,1))+(B29-MAX(B28,DATE(YEAR(B29),1,1)))/(DATE(YEAR(B29)+1,1,1)-DATE(YEAR(B29),1,1))),2)-Gaby!D29 -> 460.22 | E29: =IF(C29<=0,0,MIN(C29,ROUND(Amortización!D29*(Gaby!C29+C29)/Amortización!F28,2)-(Gaby!E29-Gaby!D29))+D29) -> 1509.09 | G29: =IF(F29="",E29,F29) -> 1509.09 | H29: =G29-D29 -> 1048.87 | I29: =ROUND(C29-H29,2) -> 37759.22
A30: =Amortización!A30 -> 25 | B30: =Amortización!B30 -> 46812 | C30: =I29 -> 37759.22 | D30: =ROUND((Gaby!C30+C30)*Amortización!$J$6*(MAX(0,DATE(YEAR(B30),1,1)-B29)/(DATE(YEAR(B29)+1,1,1)-DATE(YEAR(B29),1,1))+(B30-MAX(B29,DATE(YEAR(B30),1,1)))/(DATE(YEAR(B30)+1,1,1)-DATE(YEAR(B30),1,1))),2)-Gaby!D30 -> 418.86 | E30: =IF(C30<=0,0,MIN(C30,ROUND(Amortización!D30*(Gaby!C30+C30)/Amortización!F29,2)-(Gaby!E30-Gaby!D30))+D30) -> 1467.73 | G30: =IF(F30="",E30,F30) -> 1467.73 | H30: =G30-D30 -> 1048.87 | I30: =ROUND(C30-H30,2) -> 36710.35
A31: =Amortización!A31 -> 26 | B31: =Amortización!B31 -> 46843 | C31: =I30 -> 36710.35 | D31: =ROUND((Gaby!C31+C31)*Amortización!$J$6*(MAX(0,DATE(YEAR(B31),1,1)-B30)/(DATE(YEAR(B30)+1,1,1)-DATE(YEAR(B30),1,1))+(B31-MAX(B30,DATE(YEAR(B31),1,1)))/(DATE(YEAR(B31)+1,1,1)-DATE(YEAR(B31),1,1))),2)-Gaby!D31 -> 435.31 | E31: =IF(C31<=0,0,MIN(C31,ROUND(Amortización!D31*(Gaby!C31+C31)/Amortización!F30,2)-(Gaby!E31-Gaby!D31))+D31) -> 1484.18 | G31: =IF(F31="",E31,F31) -> 1484.18 | H31: =G31-D31 -> 1048.87 | I31: =ROUND(C31-H31,2) -> 35661.48
A32: =Amortización!A32 -> 27 | B32: =Amortización!B32 -> 46873 | C32: =I31 -> 35661.48 | D32: =ROUND((Gaby!C32+C32)*Amortización!$J$6*(MAX(0,DATE(YEAR(B32),1,1)-B31)/(DATE(YEAR(B31)+1,1,1)-DATE(YEAR(B31),1,1))+(B32-MAX(B31,DATE(YEAR(B32),1,1)))/(DATE(YEAR(B32)+1,1,1)-DATE(YEAR(B32),1,1))),2)-Gaby!D32 -> 409.23 | E32: =IF(C32<=0,0,MIN(C32,ROUND(Amortización!D32*(Gaby!C32+C32)/Amortización!F31,2)-(Gaby!E32-Gaby!D32))+D32) -> 1458.1 | G32: =IF(F32="",E32,F32) -> 1458.1 | H32: =G32-D32 -> 1048.87 | I32: =ROUND(C32-H32,2) -> 34612.61
A33: =Amortización!A33 -> 28 | B33: =Amortización!B33 -> 46904 | C33: =I32 -> 34612.61 | D33: =ROUND((Gaby!C33+C33)*Amortización!$J$6*(MAX(0,DATE(YEAR(B33),1,1)-B32)/(DATE(YEAR(B32)+1,1,1)-DATE(YEAR(B32),1,1))+(B33-MAX(B32,DATE(YEAR(B33),1,1)))/(DATE(YEAR(B33)+1,1,1)-DATE(YEAR(B33),1,1))),2)-Gaby!D33 -> 410.43 | E33: =IF(C33<=0,0,MIN(C33,ROUND(Amortización!D33*(Gaby!C33+C33)/Amortización!F32,2)-(Gaby!E33-Gaby!D33))+D33) -> 1459.3 | G33: =IF(F33="",E33,F33) -> 1459.3 | H33: =G33-D33 -> 1048.87 | I33: =ROUND(C33-H33,2) -> 33563.74
A34: =Amortización!A34 -> 29 | B34: =Amortización!B34 -> 46934 | C34: =I33 -> 33563.74 | D34: =ROUND((Gaby!C34+C34)*Amortización!$J$6*(MAX(0,DATE(YEAR(B34),1,1)-B33)/(DATE(YEAR(B33)+1,1,1)-DATE(YEAR(B33),1,1))+(B34-MAX(B33,DATE(YEAR(B34),1,1)))/(DATE(YEAR(B34)+1,1,1)-DATE(YEAR(B34),1,1))),2)-Gaby!D34 -> 385.16 | E34: =IF(C34<=0,0,MIN(C34,ROUND(Amortización!D34*(Gaby!C34+C34)/Amortización!F33,2)-(Gaby!E34-Gaby!D34))+D34) -> 1434.03 | G34: =IF(F34="",E34,F34) -> 1434.03 | H34: =G34-D34 -> 1048.87 | I34: =ROUND(C34-H34,2) -> 32514.87
A35: =Amortización!A35 -> 30 | B35: =Amortización!B35 -> 46965 | C35: =I34 -> 32514.87 | D35: =ROUND((Gaby!C35+C35)*Amortización!$J$6*(MAX(0,DATE(YEAR(B35),1,1)-B34)/(DATE(YEAR(B34)+1,1,1)-DATE(YEAR(B34),1,1))+(B35-MAX(B34,DATE(YEAR(B35),1,1)))/(DATE(YEAR(B35)+1,1,1)-DATE(YEAR(B35),1,1))),2)-Gaby!D35 -> 385.56 | E35: =IF(C35<=0,0,MIN(C35,ROUND(Amortización!D35*(Gaby!C35+C35)/Amortización!F34,2)-(Gaby!E35-Gaby!D35))+D35) -> 1434.43 | G35: =IF(F35="",E35,F35) -> 1434.43 | H35: =G35-D35 -> 1048.87 | I35: =ROUND(C35-H35,2) -> 31466
A36: =Amortización!A36 -> 31 | B36: =Amortización!B36 -> 46996 | C36: =I35 -> 31466 | D36: =ROUND((Gaby!C36+C36)*Amortización!$J$6*(MAX(0,DATE(YEAR(B36),1,1)-B35)/(DATE(YEAR(B35)+1,1,1)-DATE(YEAR(B35),1,1))+(B36-MAX(B35,DATE(YEAR(B36),1,1)))/(DATE(YEAR(B36)+1,1,1)-DATE(YEAR(B36),1,1))),2)-Gaby!D36 -> 373.12 | E36: =IF(C36<=0,0,MIN(C36,ROUND(Amortización!D36*(Gaby!C36+C36)/Amortización!F35,2)-(Gaby!E36-Gaby!D36))+D36) -> 1421.99 | G36: =IF(F36="",E36,F36) -> 1421.99 | H36: =G36-D36 -> 1048.87 | I36: =ROUND(C36-H36,2) -> 30417.13
... A65: =Amortización!A65 -> 60 | B65: =Amortización!B65 -> 47879 | C65: =I64 -> 1048.75 | D65: =ROUND((Gaby!C65+C65)*Amortización!$J$6*(MAX(0,DATE(YEAR(B65),1,1)-B64)/(DATE(YEAR(B64)+1,1,1)-DATE(YEAR(B64),1,1))+(B65-MAX(B64,DATE(YEAR(B65),1,1)))/(DATE(YEAR(B65)+1,1,1)-DATE(YEAR(B65),1,1))),2)-Gaby!D65 -> 12.48 | E65: =IF(C65<=0,0,MIN(C65,ROUND(Amortización!D65*(Gaby!C65+C65)/Amortización!F64,2)-(Gaby!E65-Gaby!D65))+D65) -> 1061.23 | G65: =IF(F65="",E65,F65) -> 1061.23 | H65: =G65-D65 -> 1048.75 | I65: =ROUND(C65-H65,2) -> 0
B66: Total | D66: =SUM(D6:D65) -> 21745.38 | F66: =SUM(F6:F65) -> 1339.77 | G66: =SUM(G6:G65) -> 72745.38 | H66: =SUM(H6:H65) -> 51000

Sheet Total
A1: Crédito total – Gaby + Gerson
A2: Suma de las dos hojas individuales: lo que pagan entre los dos cada mes es lo que se paga al banco · Verde = tomado de otra hoja · Negro = fórmula
A4: No. | B4: Fecha | C4: Pago Gaby | D4: Pago Gerson | E4: Total pagado al banco | F4: Interés | G4: Capital | H4: Saldo total | I4: Cuota según plan banco | J4: Saldo según plan banco | K4: Estado | M4: Resumen del crédito
A5: =Amortización!A5 -> 0 | B5: =Amortización!B5 -> 46053 | H5: =Gaby!I5+Gerson!I5 -> 100000 | J5: =Amortización!F5 -> 100000 | M5: Cuotas pagadas por los dos | N5: =COUNTIF(K6:K65,"Pagado") -> 8
A6: =Amortización!A6 -> 1 | B6: =Amortización!B6 -> 46081 | C6: =Gaby!G6 -> 2677.85 | D6: =Gerson!G6 -> 62.79 | E6: =C6+D6 -> 2740.64 | F6: =Gaby!D6+Gerson!D6 -> 1073.97 | G6: =E6-F6 -> 1666.67 | H6: =Gaby!I6+Gerson!I6 -> 98333.33 | I6: =Amortización!C6 -> 2740.64 | J6: =Amortización!F6 -> 98333.33 | K6: =IF(COUNT(Gaby!F6,Gerson!F6)=2,"Pagado",IF(COUNT(Gaby!F6,Gerson!F6)=1,"Parcial","Proyectado")) -> Pagado | M6: Saldo de Gaby hoy | N6: =Gaby!L14 -> 32125.5
A7: =Amortización!A7 -> 2 | B7: =Amortización!B7 -> 46112 | C7: =Gaby!G7 -> 2653.08 | D7: =Gerson!G7 -> 182.81 | E7: =C7+D7 -> 2835.89 | F7: =Gaby!D7+Gerson!D7 -> 1169.22 | G7: =E7-F7 -> 1666.67 | H7: =Gaby!I7+Gerson!I7 -> 96666.66 | I7: =Amortización!C7 -> 2835.89 | J7: =Amortización!F7 -> 96666.66 | K7: =IF(COUNT(Gaby!F7,Gerson!F7)=2,"Pagado",IF(COUNT(Gaby!F7,Gerson!F7)=1,"Parcial","Proyectado")) -> Pagado | M7: Saldo de Gerson hoy | N7: =Gerson!L14 -> 54541.14
A8: =Amortización!A8 -> 3 | B8: =Amortización!B8 -> 46142 | C8: =Gaby!G8 -> 2628.31 | D8: =Gerson!G8 -> 150.69 | E8: =C8+D8 -> 2779 | F8: =Gaby!D8+Gerson!D8 -> 1112.33 | G8: =E8-F8 -> 1666.67 | H8: =Gaby!I8+Gerson!I8 -> 94999.99 | I8: =Amortización!C8 -> 2779 | J8: =Amortización!F8 -> 94999.99 | K8: =IF(COUNT(Gaby!F8,Gerson!F8)=2,"Pagado",IF(COUNT(Gaby!F8,Gerson!F8)=1,"Parcial","Proyectado")) -> Pagado | M8: Saldo total hoy | N8: =N6+N7 -> 86666.64
A9: =Amortización!A9 -> 4 | B9: =Amortización!B9 -> 46173 | C9: =Gaby!G9 -> 2603.54 | D9: =Gerson!G9 -> 192.72 | E9: =C9+D9 -> 2796.26 | F9: =Gaby!D9+Gerson!D9 -> 1129.59 | G9: =E9-F9 -> 1666.67 | H9: =Gaby!I9+Gerson!I9 -> 93333.32 | I9: =Amortización!C9 -> 2796.26 | J9: =Amortización!F9 -> 93333.32 | K9: =IF(COUNT(Gaby!F9,Gerson!F9)=2,"Pagado",IF(COUNT(Gaby!F9,Gerson!F9)=1,"Parcial","Proyectado")) -> Pagado | M9: Saldo según plan del banco | N9: =INDEX(J5:J65,N5+1) -> 86666.64
A10: =Amortización!A10 -> 5 | B10: =Amortización!B10 -> 46203 | C10: =Gaby!G10 -> 2578.76 | D10: =Gerson!G10 -> 161.88 | E10: =C10+D10 -> 2740.64 | F10: =Gaby!D10+Gerson!D10 -> 1073.97 | G10: =E10-F10 -> 1666.67 | H10: =Gaby!I10+Gerson!I10 -> 91666.65 | I10: =Amortización!C10 -> 2740.64 | J10: =Amortización!F10 -> 91666.65 | K10: =IF(COUNT(Gaby!F10,Gerson!F10)=2,"Pagado",IF(COUNT(Gaby!F10,Gerson!F10)=1,"Parcial","Proyectado")) -> Pagado | M10: Adelantado al banco (abonos extra) | N10: =ROUND(N9-N8,2) -> 0
A11: =Amortización!A11 -> 6 | B11: =Amortización!B11 -> 46234 | C11: =Gaby!G11 -> 2553.99 | D11: =Gerson!G11 -> 202.63 | E11: =C11+D11 -> 2756.62 | F11: =Gaby!D11+Gerson!D11 -> 1089.95 | G11: =E11-F11 -> 1666.67 | H11: =Gaby!I11+Gerson!I11 -> 89999.98 | I11: =Amortización!C11 -> 2756.62 | J11: =Amortización!F11 -> 89999.98 | K11: =IF(COUNT(Gaby!F11,Gerson!F11)=2,"Pagado",IF(COUNT(Gaby!F11,Gerson!F11)=1,"Parcial","Proyectado")) -> Pagado | M11: Verificación: pagado − cuota del banco | N11: =ROUND(SUMPRODUCT((K6:K65="Pagado")*(E6:E65-I6:I65)),2) -> 0
A12: =Amortización!A12 -> 7 | B12: =Amortización!B12 -> 46265 | C12: =Gaby!G12 -> 2529.22 | D12: =Gerson!G12 -> 207.59 | E12: =C12+D12 -> 2736.81 | F12: =Gaby!D12+Gerson!D12 -> 1070.14 | G12: =E12-F12 -> 1666.67 | H12: =Gaby!I12+Gerson!I12 -> 88333.31 | I12: =Amortización!C12 -> 2736.81 | J12: =Amortización!F12 -> 88333.31 | K12: =IF(COUNT(Gaby!F12,Gerson!F12)=2,"Pagado",IF(COUNT(Gaby!F12,Gerson!F12)=1,"Parcial","Proyectado")) -> Pagado
A13: =Amortización!A13 -> 8 | B13: =Amortización!B13 -> 46295 | C13: =Gaby!G13 -> 2504.45 | D13: =Gerson!G13 -> 178.66 | E13: =C13+D13 -> 2683.11 | F13: =Gaby!D13+Gerson!D13 -> 1016.44 | G13: =E13-F13 -> 1666.67 | H13: =Gaby!I13+Gerson!I13 -> 86666.64 | I13: =Amortización!C13 -> 2683.11 | J13: =Amortización!F13 -> 86666.64 | K13: =IF(COUNT(Gaby!F13,Gerson!F13)=2,"Pagado",IF(COUNT(Gaby!F13,Gerson!F13)=1,"Parcial","Proyectado")) -> Pagado | M13: Proyección hasta el final
A14: =Amortización!A14 -> 9 | B14: =Amortización!B14 -> 46326 | C14: =Gaby!G14 -> 999.79 | D14: =Gerson!G14 -> 1697.38 | E14: =C14+D14 -> 2697.17 | F14: =Gaby!D14+Gerson!D14 -> 1030.5 | G14: =E14-F14 -> 1666.67 | H14: =Gaby!I14+Gerson!I14 -> 84999.97 | I14: =Amortización!C14 -> 2697.17 | J14: =Amortización!F14 -> 84999.97 | K14: =IF(COUNT(Gaby!F14,Gerson!F14)=2,"Pagado",IF(COUNT(Gaby!F14,Gerson!F14)=1,"Parcial","Proyectado")) -> Proyectado | M14: Total de intereses | N14: =F66 -> 35533.42
A15: =Amortización!A15 -> 10 | B15: =Amortización!B15 -> 46356 | C15: =Gaby!G15 -> 980.35 | D15: =Gerson!G15 -> 1664.4 | E15: =C15+D15 -> 2644.75 | F15: =Gaby!D15+Gerson!D15 -> 978.08 | G15: =E15-F15 -> 1666.67 | H15: =Gaby!I15+Gerson!I15 -> 83333.3 | I15: =Amortización!C15 -> 2644.75 | J15: =Amortización!F15 -> 83333.3 | K15: =IF(COUNT(Gaby!F15,Gerson!F15)=2,"Pagado",IF(COUNT(Gaby!F15,Gerson!F15)=1,"Parcial","Proyectado")) -> Proyectado | M15: Total pagado al banco | N15: =E66 -> 135533.42
A16: =Amortización!A16 -> 11 | B16: =Amortización!B16 -> 46387 | C16: =Gaby!G16 -> 985.09 | D16: =Gerson!G16 -> 1672.45 | E16: =C16+D16 -> 2657.54 | F16: =Gaby!D16+Gerson!D16 -> 990.87 | G16: =E16-F16 -> 1666.67 | H16: =Gaby!I16+Gerson!I16 -> 81666.63 | I16: =Amortización!C16 -> 2657.54 | J16: =Amortización!F16 -> 81666.63 | K16: =IF(COUNT(Gaby!F16,Gerson!F16)=2,"Pagado",IF(COUNT(Gaby!F16,Gerson!F16)=1,"Parcial","Proyectado")) -> Proyectado | M16: Total según plan del banco | N16: =I66 -> 135533.42
A17: =Amortización!A17 -> 12 | B17: =Amortización!B17 -> 46418 | C17: =Gaby!G17 -> 977.75 | D17: =Gerson!G17 -> 1659.97 | E17: =C17+D17 -> 2637.72 | F17: =Gaby!D17+Gerson!D17 -> 971.05 | G17: =E17-F17 -> 1666.67 | H17: =Gaby!I17+Gerson!I17 -> 79999.96 | I17: =Amortización!C17 -> 2637.72 | J17: =Amortización!F17 -> 79999.96 | K17: =IF(COUNT(Gaby!F17,Gerson!F17)=2,"Pagado",IF(COUNT(Gaby!F17,Gerson!F17)=1,"Parcial","Proyectado")) -> Proyectado
A18: =Amortización!A18 -> 13 | B18: =Amortización!B18 -> 46446 | C18: =Gaby!G18 -> 936.28 | D18: =Gerson!G18 -> 1589.57 | E18: =C18+D18 -> 2525.85 | F18: =Gaby!D18+Gerson!D18 -> 859.18 | G18: =E18-F18 -> 1666.67 | H18: =Gaby!I18+Gerson!I18 -> 78333.29 | I18: =Amortización!C18 -> 2525.85 | J18: =Amortización!F18 -> 78333.29 | K18: =IF(COUNT(Gaby!F18,Gerson!F18)=2,"Pagado",IF(COUNT(Gaby!F18,Gerson!F18)=1,"Parcial","Proyectado")) -> Proyectado
A19: =Amortización!A19 -> 14 | B19: =Amortización!B19 -> 46477 | C19: =Gaby!G19 -> 963.06 | D19: =Gerson!G19 -> 1635.03 | E19: =C19+D19 -> 2598.09 | F19: =Gaby!D19+Gerson!D19 -> 931.42 | G19: =E19-F19 -> 1666.67 | H19: =Gaby!I19+Gerson!I19 -> 76666.62 | I19: =Amortización!C19 -> 2598.09 | J19: =Amortización!F19 -> 76666.62 | K19: =IF(COUNT(Gaby!F19,Gerson!F19)=2,"Pagado",IF(COUNT(Gaby!F19,Gerson!F19)=1,"Parcial","Proyectado")) -> Proyectado
A20: =Amortización!A20 -> 15 | B20: =Amortización!B20 -> 46507 | C20: =Gaby!G20 -> 944.81 | D20: =Gerson!G20 -> 1604.05 | E20: =C20+D20 -> 2548.86 | F20: =Gaby!D20+Gerson!D20 -> 882.19 | G20: =E20-F20 -> 1666.67 | H20: =Gaby!I20+Gerson!I20 -> 74999.95 | I20: =Amortización!C20 -> 2548.86 | J20: =Amortización!F20 -> 74999.95 | K20: =IF(COUNT(Gaby!F20,Gerson!F20)=2,"Pagado",IF(COUNT(Gaby!F20,Gerson!F20)=1,"Parcial","Proyectado")) -> Proyectado
A21: =Amortización!A21 -> 16 | B21: =Amortización!B21 -> 46538 | C21: =Gaby!G21 -> 948.36 | D21: =Gerson!G21 -> 1610.09 | E21: =C21+D21 -> 2558.45 | F21: =Gaby!D21+Gerson!D21 -> 891.78 | G21: =E21-F21 -> 1666.67 | H21: =Gaby!I21+Gerson!I21 -> 73333.28 | I21: =Amortización!C21 -> 2558.45 | J21: =Amortización!F21 -> 73333.28 | K21: =IF(COUNT(Gaby!F21,Gerson!F21)=2,"Pagado",IF(COUNT(Gaby!F21,Gerson!F21)=1,"Parcial","Proyectado")) -> Proyectado
A22: =Amortización!A22 -> 17 | B22: =Amortización!B22 -> 46568 | C22: =Gaby!G22 -> 930.59 | D22: =Gerson!G22 -> 1579.92 | E22: =C22+D22 -> 2510.51 | F22: =Gaby!D22+Gerson!D22 -> 843.84 | G22: =E22-F22 -> 1666.67 | H22: =Gaby!I22+Gerson!I22 -> 71666.61 | I22: =Amortización!C22 -> 2510.51 | J22: =Amortización!F22 -> 71666.61 | K22: =IF(COUNT(Gaby!F22,Gerson!F22)=2,"Pagado",IF(COUNT(Gaby!F22,Gerson!F22)=1,"Parcial","Proyectado")) -> Proyectado
A23: =Amortización!A23 -> 18 | B23: =Amortización!B23 -> 46599 | C23: =Gaby!G23 -> 933.67 | D23: =Gerson!G23 -> 1585.15 | E23: =C23+D23 -> 2518.82 | F23: =Gaby!D23+Gerson!D23 -> 852.15 | G23: =E23-F23 -> 1666.67 | H23: =Gaby!I23+Gerson!I23 -> 69999.94 | I23: =Amortización!C23 -> 2518.82 | J23: =Amortización!F23 -> 69999.94 | K23: =IF(COUNT(Gaby!F23,Gerson!F23)=2,"Pagado",IF(COUNT(Gaby!F23,Gerson!F23)=1,"Parcial","Proyectado")) -> Proyectado
